Workbook
Name List_cando: _xlfn.ANCHORARRAY('Evaluate Interview form (Demo)'!$AB$99)
Name List_Willdo: _xlfn.ANCHORARRAY('Evaluate Interview form (Demo)'!$AC$99)
Name List_Willfit: _xlfn.ANCHORARRAY('Evaluate Interview form (Demo)'!$AD$99)

Sheet Evaluate Interview form
A1: แบบประเมินการสัมภาษณ์งาน
A2: ชื่อ-นามสกุล: | G2: ตำแหน่งที่สมัคร (Positions): | L2: บทบาท (Role):
A3: บริษัท: | G3: ฝ่าย (Department): | L3: แผนก (Section):
A4: วันที่สัมภาษณ์: | G4: ผู้สัมภาษณ์ (Interviewer): | L4: ผู้สรรหา (Recruiter): | T4: Can do | U4: Eng Can do | V4: ความหมาย Can do | W4: Will do | X4: Eng Will do | Y4: ความหมาย Will do | Z4: Will fit | AA4: Eng Will fit | AB4: ความหมาย Will fit | AC4: Score
A5: บันทึกผลการสัมภาษณ์ | T5: การคิดวิเคราะห์ & การตัดสินใจ (Analytical Thinking & Decision Making) | U5: Analytical Thinking | V5: • ความสามารถในการวิเคราะห์ ประมวลข้อมูล และสรุปประเด็นสำคัญ • การวิเคราะห์และตัดสินใจบนพื้นฐานของข้อมูลอย่างสมเหตุสมผล | W5: การคิดเชิงวิเคราะห์ (Analytical Thinking) | X5: Analytical Thinking | Y5: • ความสามารถในการวิเคราะห์ ประมวลข้อมูล และสรุปประเด็นสำคัญ • การวิเคราะห์และตัดสินใจบนพื้นฐานของข้อมูลอย่างสมเหตุสมผล | Z5: พัฒนาทักษะตัวเองอยู่เสมอ (Self-Development) | AA5: Self-Development | AB5: • พฤติกรรมในการพัฒนาทักษะและความสามารถของตนเองอยู่เสมอ | AC5: 5
A6: หลักพิจารณา | B6: รายการประเมิน | G6: เลือกสมรรถนะที่ต้องการประเมิน | I6: คาดหวัง | J6: คะแนน | K6: ผลประเมิน | L6: หมายเหตุ/ ความคิดเห็น | T6: ความเชี่ยวชาญด้านเทคนิค (Technical Skill) | U6: Technical Skill | V6: • ทักษะด้านการเขียนโปรแกรมหรือเครื่องมื่อต่างๆ | W6: การแก้ไขปัญหา (Problem Solving) | X6: Problem Solving | Y6: • การวิเคราะห์สถานการณ์และการคิดอย่างเป็นระบบ • ความคิดสร้างสรรค์ในการหาทางออก | Z6: การปรับตัว & การทำงานร่วมกันเป็นทีม (Adaptability & Teamwork) | AA6: Teamwork & Adaptability | AB6: • สามารถปรับตัวทำงานร่วมกับทีมได้ดี • พร้อมรับฟังและยอมรับความเห็นต่าง | AC6: 4
A7: (Pillar) | G7: (Competency) | I7: (Expect) | J7: (Score) | K7: (Result) | L7: (Note/ Comment) | T7: ความคล่องตัวในการเรียนรู้ (Learning Agility) | U7: Learning Agility | V7: • เรียนรู้เทคโนโลยีใหม่ ๆ ได้เร็วและต่อเนื่อง | W7: ความเชี่ยวชาญด้านเทคนิค (Technical Skill) | X7: Technical Skill | Y7: • ทักษะด้านการเขียนโปรแกรมหรือเครื่องมื่อต่างๆ | Z7: ทักษะการสื่อสารและเจรจา (Communication & Negotiation) | AA7: Communication & Negotiation | AB7: • สามารถในการอธิบายแนวคิด หรือ เรื่องราวต่างๆ ได้ชัดเจน | AC7: 3
A8: ที่ต้องทำ (Can do) | B8: 1 | C8: =IF(ISBLANK($G$8),"โปรดเลือกสมรรถนะที่ต้องการประเมิน",$G$8) -> ความเชี่ยวชาญด้านเทคนิค (Technical Skill) | G8: ความเชี่ยวชาญด้านเทคนิค (Technical Skill) | I8: 2 | J8: 2 | K8: =IF($J$8="","ระบุ",IF($J$8<$I$8,"Below",IF($J$8=$I$8,"Meet","Exceed"))) -> Meet | L8: ผล: | M8: {=_xlfn.IFS($J$8=1,'Competency detail'!$D$14,$J$8=2,'Competency detail'!$D$15,$J$8=3,'Competency detail'!$D$16,$J$8=4,'Competency detail'!$D$17,$J$8=5,'Competency detail'!$D$18)} -> มีทักษะความรู้บ้างเล็กน้อยถึงปานกลาง/ ต้องมีคนแนะนำ เช่น เข้าใจหลักการของการแก้ไขปัญหาง่ายๆ | T8: การวางแผนและการจัดระเบียบ (Planning & Organizing) | U8: Planning & Organizing | V8: • สามารถวางแผนการจัดการปัญหาหรือโปรเจกต์ได้อย่างมีประสิทธิภาพและลื่นไหล | W8: ความคล่องตัวในการเรียนรู้ (Learning Agility) | X8: Learning Agility | Y8: • เรียนรู้เทคโนโลยีใหม่ ๆ ได้เร็วและต่อเนื่อง | AC8: 2
C9: เกณฑ์ทักษะความสามารถที่คาดหวัง: | L9: ทีม: | T9: ทักษะการสื่อสารและเจรจา (Communication & Negotiation) | U9: Communication & Negotiation | V9: • สามารถในการอธิบายแนวคิด หรือ เรื่องราวต่างๆ ได้ชัดเจน • สามารถจูงใจหรือโน้วน้าวผู้อื่น ได้ | W9: การวางแผนและการจัดระเบียบ (Planning & Organizing) | X9: Planning & Organizing | Y9: • สามารถวางแผนการจัดการปัญหาหรือโปรเจกต์ได้อย่างมีประสิทธิภาพและลื่นไหล | Z9: มีความซื่อสัตย์ในการทำงาน (Work Ethic) | AA9: Work Ethic | AB9: • พฤติกรรมที่ซื่อตรงในการทำงาน ไม่ปกปิดข้อมูลใดที่อาจก่อให้เกิดความเสียหาย | AC9: 1
C10: {=_xlfn.IFS($I$8=1,'Competency detail'!$D$14,$I$8=2,'Competency detail'!$D$15,$I$8=3,'Competency detail'!$D$16,$I$8=4,'Competency detail'!$D$17,$I$8=5,'Competency detail'!$D$18)} -> มีทักษะความรู้บ้างเล็กน้อยถึงปานกลาง/ ต้องมีคนแนะนำ เช่น เข้าใจหลักการของการแก้ไขปัญหาง่ายๆ | T10: มีใจรักการบริการและพร้อมช่วยเหลือลูกค้า (Service Mindset) | U10: Service Mindset | V10: • ความตั้งใจ มุ่งมั่น ใส่ใจ และเต็มใจที่จะให้บริการลูกค้าอย่างดีที่สุด | W10: การจัดการเวลา (Time Management) | X10: Time Management | Y10: • สามารถบริหารเวลาในการทำงานได้อย่างเหมาะสม | Z10: เข้าใจและตอบสนองความต้องการ & ใจรักการบริการ (Customer Focus & Service Mindset) | AA10: Customer Focus | AB10: • สามารถรวบรวมข้อมูล วิเคราะห์ กระทั่งเข้าใจและตอบสนองความต้องการของลูกค้าอย่างแท้จริงอย่างเป็นมิตร
T11: การแก้ไขปัญหา (Problem Solving) | U11: Problem Solving | V11: • การวิเคราะห์สถานการณ์และการคิดอย่างเป็นระบบ • ความคิดสร้างสรรค์ในการหาทางออก | W11: ทักษะการสื่อสารและเจรจา (Communication & Negotiation) | X11: Communication & Negotiation | Y11: • สามารถในการอธิบายแนวคิด หรือ เรื่องราวต่างๆ ได้ชัดเจน • สามารถจูงใจหรือโน้วน้าวผู้อื่น ได้ | Z11: ความกระตือรือร้น & ทัศนคติเชิงบวก (Proactive & Growth Mindset) | AA11: Proactive & Growth Mindset | AB11: • ความกระตือรือร้นที่จะทำงาน หาความรู้ วิธีการรับมือกับปัญหา
B12: 2 | C12: =IF(ISBLANK($G$12),"โปรดเลือกสมรรถนะที่ต้องการประเมิน",$G$12) -> การแก้ไขปัญหา (Problem Solving) | G12: การแก้ไขปัญหา (Problem Solving) | I12: 3 | J12: 3 | K12: =IF($J$12="","ระบุ",IF($J$12<$I$12,"Below",IF($J$12=$I$12,"Meet","Exceed"))) -> Meet | L12: ผล: | M12: {=_xlfn.IFS($J$12=1,'Competency detail'!$D$8,$J$12=2,'Competency detail'!$D$9,$J$12=3,'Competency detail'!$D$10,$J$12=4,'Competency detail'!$D$11,$J$12=5,'Competency detail'!$D$12)} -> สามารถแก้ไขปัญหาที่ซับซ้อนปานกลางให้สำเร็จได้ด้วยตนเอง เช่น ไล่ code แก้ bug ที่มีความซับซ้อนเองได้ | W12: มุ่งมั่นให้งานเสร็จและมีคุณภาพ (Drive for Achievement) | X12: Drive for Achievement | Y12: • ผู้ที่มักตั้งเป้าหมายที่ชัดเจน และมุ่งมั่นอย่างสูงเพื่อให้งานเสร็จและมีคุณภาพ
C13: เกณฑ์ทักษะความสามารถที่คาดหวัง: | L13: ทีม: | W13: รับผิดชอบงานของตนเอง (Accountability / Ownership) | X13: Accountability / Ownership | Y13: • พฤติกรรมที่รับผิดชอบงานของตนเองให้เสร็จตามเวลาที่กำหนด
C14: {=_xlfn.IFS($I$12=1,'Competency detail'!$D$8,$I$12=2,'Competency detail'!$D$9,$I$12=3,'Competency detail'!$D$10,$I$12=4,'Competency detail'!$D$11,$I$12=5,'Competency detail'!$D$12)} -> สามารถแก้ไขปัญหาที่ซับซ้อนปานกลางให้สำเร็จได้ด้วยตนเอง เช่น ไล่ code แก้ bug ที่มีความซับซ้อนเองได้ | W14: ความกระตือรือร้น & ทัศนคติเชิงบวก (Proactive & Growth Mindset) | X14: Proactive & Growth Mindset | Y14: • ความกระตือรือร้นที่จะทำงาน หาความรู้ วิธีการรับมือกับปัญหา
W15: พัฒนาทักษะตัวเองอยู่เสมอ (Self-Development) | X15: Self-Development | Y15: • พฤติกรรมในการพัฒนาทักษะและความสามารถของตนเองอยู่เสมอ
B16: 3 | C16: =IF(ISBLANK($G$16),"โปรดเลือกสมรรถนะที่ต้องการประเมิน",$G$16) -> ทักษะการสื่อสารและเจรจา (Communication & Negotiation) | G16: ทักษะการสื่อสารและเจรจา (Communication & Negotiation) | I16: 2 | J16: 2 | K16: =IF($J$16="","ระบุ",IF($J$16<$I$16,"Below",IF($J$16=$I$16,"Meet","Exceed"))) -> Meet | L16: ผล: | M16: {=_xlfn.IFS($G$16=$AF$78,_xlfn.XLOOKUP($J$16,$AG$78:$AG$82,$AH$78:$AH$82,"",0),$G$16=$AF$84,_xlfn.XLOOKUP($J$16,$AG$84:$AG$88,AH84:AH88,"",0),$G$16=$AF$90,_xlfn.XLOOKUP($J$16,AG90:AG94,AH90:AH94,"",0),$G$16=AF96,_xlfn.XLOOKUP(J16,AG96:AG100,AH96:AH100,"",0),$G$16=AF102,_xlfn.XLOOKUP(J16,AG102:AG106,AH102:AH106,"",0),$G$16=$AF$108,_xlfn.XLOOKUP(J16,AG108:AG112,AH108:AH112,"",0),G16=AF114,_xlfn.XLOOKUP(J16,AG114:AG118,AH114:AH118,"",0),G16=AF120,_xlfn.XLOOKUP(J16,AG120:AG124,AH120:AH124,"",0),G16=AF126,_xlfn.XLOOKUP(J16,AG126:AG130,AH126:AH130,"",0),G16=AF132,_xlfn.XLOOKUP(J16,AG132:AG136,AH132:AH136,"",0),G16=AF138,_xlfn.XLOOKUP(J16,AG138:AG142,AH138:AH142,"",0),G16=AF144,_xlfn.XLOOKUP(J16,AG144:AG148,AH144:AH148,"",0),G16="","โปรดระบุเกณฑ์ความสามารถ")} -> สื่อสารรู้เรื่อง เช่น เข้าใจเนื่อหาที่ผู้สมัครต้องการสื่อสาร | W16: เข้าใจและตอบสนองความต้องการ & ใจรักการบริการ (Customer Focus & Service Mindset) | X16: Customer Focus & Service Mindset | Y16: • สามารถรวบรวมข้อมูล วิเคราะห์ กระทั่งเข้าใจและตอบสนองความต้องการของลูกค้าอย่างแท้จริงอย่างเป็นมิตร
C17: เกณฑ์ทักษะความสามารถที่คาดหวัง: | L17: ทีม:
C18: {=_xlfn.IFS($G$16=$AF$78,_xlfn.XLOOKUP($I$16,$AG$78:$AG$82,$AH$78:$AH$82,"",0),$G$16=$AF$84,_xlfn.XLOOKUP($I$16,$AG$84:$AG$88,AH84:AH88,"",0),$G$16=$AF$90,_xlfn.XLOOKUP($I$16,AG90:AG94,AH90:AH94,"",0),$G$16=AF96,_xlfn.XLOOKUP(I16,AG96:AG100,AH96:AH100,"",0),$G$16=AF102,_xlfn.XLOOKUP(I16,AG102:AG106,AH102:AH106,"",0),$G$16=$AF$108,_xlfn.XLOOKUP(I16,AG108:AG112,AH108:AH112,"",0),G16=AF114,_xlfn.XLOOKUP(I16,AG114:AG118,AH114:AH118,"",0),G16=AF120,_xlfn.XLOOKUP(I16,AG120:AG124,AH120:AH124,"",0),G16=AF126,_xlfn.XLOOKUP(I16,AG126:AG130,AH126:AH130,"",0),G16=AF132,_xlfn.XLOOKUP(I16,AG132:AG136,AH132:AH136,"",0),G16=AF138,_xlfn.XLOOKUP(I16,AG138:AG142,AH138:AH142,"",0),G16=AF144,_xlfn.XLOOKUP(I16,AG144:AG148,AH144:AH148,"",0),G16="","โปรดระบุเกณฑ์ความสามารถ")} -> สื่อสารรู้เรื่อง เช่น เข้าใจเนื่อหาที่ผู้สมัครต้องการสื่อสาร
A20: ที่ชอบทำ (Will do) | B20: 4 | C20: =IF(ISBLANK($G$20),"โปรดเลือกสมรรถนะที่ต้องการประเมิน",$G$20) -> ทักษะการสื่อสารและเจรจา (Communication & Negotiation) | G20: ทักษะการสื่อสารและเจรจา (Communication & Negotiation) | I20: 2 | J20: 3 | K20: =IF($J$20="","ระบุ",IF($J$20<$I$20,"Below",IF($J$20=$I$20,"Meet","Exceed"))) -> Exceed | L20: ผล: | M20: {=_xlfn.IFS($G$20=$AF$78,_xlfn.XLOOKUP($J$20,$AG$78:$AG$82,$AH$78:$AH$82,"",0),$G$20=$AF$84,_xlfn.XLOOKUP($J$20,$AG$84:$AG$88,AH84:AH88,"",0),$G$20=$AF$90,_xlfn.XLOOKUP($J$20,AG90:AG94,AH90:AH94,"",0),$G$20=AF96,_xlfn.XLOOKUP(J20,AG96:AG100,AH96:AH100,"",0),$G$20=AF102,_xlfn.XLOOKUP(J20,AG102:AG106,AH102:AH106,"",0),$G$20=$AF$108,_xlfn.XLOOKUP(J20,AG108:AG112,AH108:AH112,"",0),G20=AF114,_xlfn.XLOOKUP(J20,AG114:AG118,AH114:AH118,"",0),G20=AF120,_xlfn.XLOOKUP(J20,AG120:AG124,AH120:AH124,"",0),G20=AF126,_xlfn.XLOOKUP(J20,AG126:AG130,AH126:AH130,"",0),G20=AF132,_xlfn.XLOOKUP(J20,AG132:AG136,AH132:AH136,"",0),G20=AF138,_xlfn.XLOOKUP(J20,AG138:AG142,AH138:AH142,"",0),G20=AF144,_xlfn.XLOOKUP(J20,AG144:AG148,AH144:AH148,"",0),G20="","โปรดระบุเกณฑ์ความสามารถ")} -> 1. สื่อสารได้อย่างคล่องแคล่ว 2. ถาม-ตอบ ตรงประเด็น อธิบายแนวคิดง่ายได้ชัดเจน 3. เจราต่อรองกับคนในทีมและต่างทีมได้
C21: เกณฑ์ทักษะความสามารถที่คาดหวัง: | L21: ทีม:
C22: {=_xlfn.IFS($G$20=$AF$78,_xlfn.XLOOKUP($I$20,$AG$78:$AG$82,$AH$78:$AH$82,"",0),$G$20=$AF$84,_xlfn.XLOOKUP($I$20,$AG$84:$AG$88,AH84:AH88,"",0),$G$20=$AF$90,_xlfn.XLOOKUP($I$20,AG90:AG94,AH90:AH94,"",0),$G$20=AF96,_xlfn.XLOOKUP(I20,AG96:AG100,AH96:AH100,"",0),$G$20=AF102,_xlfn.XLOOKUP(I20,AG102:AG106,AH102:AH106,"",0),$G$20=$AF$108,_xlfn.XLOOKUP(I20,AG108:AG112,AH108:AH112,"",0),G20=AF114,_xlfn.XLOOKUP(I20,AG114:AG118,AH114:AH118,"",0),G20=AF120,_xlfn.XLOOKUP(I20,AG120:AG124,AH120:AH124,"",0),G20=AF126,_xlfn.XLOOKUP(I20,AG126:AG130,AH126:AH130,"",0),G20=AF132,_xlfn.XLOOKUP(I20,AG132:AG136,AH132:AH136,"",0),G20=AF138,_xlfn.XLOOKUP(I20,AG138:AG142,AH138:AH142,"",0),G20=AF144,_xlfn.XLOOKUP(I20,AG144:AG148,AH144:AH148,"",0),G20="","โปรดระบุเกณฑ์ความสามารถ")} -> สื่อสารรู้เรื่อง เช่น เข้าใจเนื่อหาที่ผู้สมัครต้องการสื่อสาร
B24: 5 | C24: =IF(ISBLANK($G$24),"โปรดเลือกสมรรถนะที่ต้องการประเมิน",$G$24) -> การปรับตัว & การทำงานร่วมกันเป็นทีม (Adaptability & Teamwork) | G24: การปรับตัว & การทำงานร่วมกันเป็นทีม (Adaptability & Teamwork) | I24: 2 | J24: 1 | K24: =IF($J$24="","ระบุ",IF($J$24<$I$24,"Below",IF($J$24=$I$24,"Meet","Exceed"))) -> Below | L24: ผล: | M24: {=_xlfn.IFS($G$24=$AF$78,_xlfn.XLOOKUP($J$24,$AG$78:$AG$82,$AH$78:$AH$82,"",0),$G$24=$AF$84,_xlfn.XLOOKUP($J$24,$AG$84:$AG$88,AH84:AH88,"",0),$G$24=$AF$90,_xlfn.XLOOKUP($J$24,AG90:AG94,AH90:AH94,"",0),$G$24=AF96,_xlfn.XLOOKUP(J24,AG96:AG100,AH96:AH100,"",0),$G$24=AF102,_xlfn.XLOOKUP(J24,AG102:AG106,AH102:AH106,"",0),$G$24=$AF$108,_xlfn.XLOOKUP(J24,AG108:AG112,AH108:AH112,"",0),G24=AF114,_xlfn.XLOOKUP(J24,AG114:AG118,AH114:AH118,"",0),G24=AF120,_xlfn.XLOOKUP(J24,AG120:AG124,AH120:AH124,"",0),G24=AF126,_xlfn.XLOOKUP(J24,AG126:AG130,AH126:AH130,"",0),G24=AF132,_xlfn.XLOOKUP(J24,AG132:AG136,AH132:AH136,"",0),G24=AF138,_xlfn.XLOOKUP(J24,AG138:AG142,AH138:AH142,"",0),G24=AF144,_xlfn.XLOOKUP(J24,AG144:AG148,AH144:AH148,"",0),G24="","โปรดระบุเกณฑ์ความสามารถ")} -> ชอบทำงานคนเดียว/ ไม่ฟังความคิดเห็น /ไม่พูด / พูดไม่รู้เรื่อง
C25: เกณฑ์ทักษะความสามารถที่คาดหวัง: | L25: ทีม: | T25: Part | U25: No | V25: Expect score | W25: Score | X25: Result | Y25: Interpreting | Z25: Can do, Best fit ,Cann't do, Not fit
C26: {=_xlfn.IFS($G$24=$AF$78,_xlfn.XLOOKUP($I$24,$AG$78:$AG$82,$AH$78:$AH$82,"",0),$G$24=$AF$84,_xlfn.XLOOKUP($I$24,$AG$84:$AG$88,AH84:AH88,"",0),$G$24=$AF$90,_xlfn.XLOOKUP($I$24,AG90:AG94,AH90:AH94,"",0),$G$24=AF96,_xlfn.XLOOKUP(I24,AG96:AG100,AH96:AH100,"",0),$G$24=AF102,_xlfn.XLOOKUP(I24,AG102:AG106,AH102:AH106,"",0),$G$24=$AF$108,_xlfn.XLOOKUP(I24,AG108:AG112,AH108:AH112,"",0),G24=AF114,_xlfn.XLOOKUP(I24,AG114:AG118,AH114:AH118,"",0),G24=AF120,_xlfn.XLOOKUP(I24,AG120:AG124,AH120:AH124,"",0),G24=AF126,_xlfn.XLOOKUP(I24,AG126:AG130,AH126:AH130,"",0),G24=AF132,_xlfn.XLOOKUP(I24,AG132:AG136,AH132:AH136,"",0),G24=AF138,_xlfn.XLOOKUP(I24,AG138:AG142,AH138:AH142,"",0),G24=AF144,_xlfn.XLOOKUP(I24,AG144:AG148,AH144:AH148,"",0),G24="","โปรดระบุเกณฑ์ความสามารถ")} -> รับฟังความคิดเห็น แต่ยังยึดตนเป็นศุนย์กลางอยู่บ้าง/ ทัศนคติไม่ตรงกัน/ ตรรกะในการคิดแตกต่างกันอยู่บ้าง | T26: Can do | U26: 1 | V26: =$I$8 -> 2 | W26: =$J$8 -> 2 | X26: =IF($J$8<$I$8,1,IF($J$8=$I$8,2,3)) -> 2
T27: Can do | U27: 2 | V27: =$I$12 -> 3 | W27: =$J$12 -> 3 | X27: =IF($J$12<$I$12,1,IF($J$12=$I$12,2,3)) -> 2
A28: ที่เหมาะสม (Will fit) | B28: 6 | C28: =IF(ISBLANK($G$28),"โปรดเลือกสมรรถนะที่ต้องการประเมิน",$G$28) -> การปรับตัว & การทำงานร่วมกันเป็นทีม (Adaptability & Teamwork) | G28: การปรับตัว & การทำงานร่วมกันเป็นทีม (Adaptability & Teamwork) | I28: 2 | J28: 3 | K28: =IF($J$28="","ระบุ",IF($J$28<$I$28,"Below",IF($J$28=$I$28,"Meet","Exceed"))) -> Exceed | L28: ผล: | M28: {=_xlfn.IFS($G$28=$AF$78,_xlfn.XLOOKUP($J$28,$AG$78:$AG$82,$AH$78:$AH$82,"",0),$G$28=$AF$84,_xlfn.XLOOKUP($J$28,$AG$84:$AG$88,AH84:AH88,"",0),$G$28=$AF$90,_xlfn.XLOOKUP($J$28,AG90:AG94,AH90:AH94,"",0),$G$28=AF96,_xlfn.XLOOKUP($J$28,AG96:AG100,AH96:AH100,"",0),$G$28=AF102,_xlfn.XLOOKUP(J28,AG102:AG106,AH102:AH106,"",0),$G$28=$AF$108,_xlfn.XLOOKUP($J$28,AG108:AG112,AH108:AH112,"",0),G28=AF114,_xlfn.XLOOKUP(J28,AG114:AG118,AH114:AH118,"",0),G28=AF120,_xlfn.XLOOKUP(J28,AG120:AG124,AH120:AH124,"",0),G28=AF126,_xlfn.XLOOKUP(J28,AG126:AG130,AH126:AH130,"",0),G28=AF132,_xlfn.XLOOKUP(J28,AG132:AG136,AH132:AH136,"",0),G28=AF138,_xlfn.XLOOKUP(J28,AG138:AG142,AH138:AH142,"",0),G28=AF144,_xlfn.XLOOKUP(J28,AG144:AG148,AH144:AH148,"",0),G28="","โปรดระบุเกณฑ์ความสามารถ")} -> 1. มีความยืดหยุ่น 2. พร้อมรับฟังความคิดเห็น 3. สื่อสารกับทีมได้ดีพอประมาณ | T28: Can do | U28: 3 | V28: =$I$16 -> 2 | W28: =$J$16 -> 2 | X28: =IF($J$16<$I$16,1,IF($J$16=$I$16,2,3)) -> 2
C29: เกณฑ์ทักษะความสามารถที่คาดหวัง: | L29: ทีม: | T29: Will do | U29: 4 | V29: =$I$20 -> 2 | W29: =$J$20 -> 3 | X29: =IF($J$20<$I$20,1,IF($J$20=$I$20,2,3)) -> 3
C30: {=_xlfn.IFS($G$28=$AF$78,_xlfn.XLOOKUP($I$28,$AG$78:$AG$82,$AH$78:$AH$82,"",0),$G$28=$AF$84,_xlfn.XLOOKUP($I$28,$AG$84:$AG$88,AH84:AH88,"",0),$G$28=$AF$90,_xlfn.XLOOKUP($I$28,AG90:AG94,AH90:AH94,"",0),$G$28=AF96,_xlfn.XLOOKUP($I$28,AG96:AG100,AH96:AH100,"",0),$G$28=AF102,_xlfn.XLOOKUP(I28,AG102:AG106,AH102:AH106,"",0),$G$28=$AF$108,_xlfn.XLOOKUP($I$28,AG108:AG112,AH108:AH112,"",0),G28=AF114,_xlfn.XLOOKUP(I28,AG114:AG118,AH114:AH118,"",0),G28=AF120,_xlfn.XLOOKUP(I28,AG120:AG124,AH120:AH124,"",0),G28=AF126,_xlfn.XLOOKUP(I28,AG126:AG130,AH126:AH130,"",0),G28=AF132,_xlfn.XLOOKUP(I28,AG132:AG136,AH132:AH136,"",0),G28=AF138,_xlfn.XLOOKUP(I28,AG138:AG142,AH138:AH142,"",0),G28=AF144,_xlfn.XLOOKUP(I28,AG144:AG148,AH144:AH148,"",0),G28="","โปรดระบุเกณฑ์ความสามารถ")} -> รับฟังความคิดเห็น แต่ยังยึดตนเป็นศุนย์กลางอยู่บ้าง/ ทัศนคติไม่ตรงกัน/ ตรรกะในการคิดแตกต่างกันอยู่บ้าง | T30: Will do | U30: 5 | V30: =$I$24 -> 2 | W30: =$J$24 -> 1 | X30: =IF($J$24<$I$24,1,IF($J$24=$I$24,2,3)) -> 1
T31: Will fit | U31: 6 | V31: =$I$28 -> 2 | W31: =$J$28 -> 3 | X31: =IF($J$28<$I$28,1,IF($J$28=$I$28,2,3)) -> 3
B32: 7 | C32: =IF(ISBLANK($G$32),"โปรดเลือกสมรรถนะที่ต้องการประเมิน",$G$32) -> พัฒนาทักษะตัวเองอยู่เสมอ (Self-Development) | G32: พัฒนาทักษะตัวเองอยู่เสมอ (Self-Development) | I32: 2 | J32: 2 | K32: =IF($J$32="","ระบุ",IF($J$32<$I$32,"Below",IF($J$32=$I$32,"Meet","Exceed"))) -> Meet | L32: ผล: | M32: {=_xlfn.IFS($G$32=$AF$78,_xlfn.XLOOKUP($J$32,$AG$78:$AG$82,$AH$78:$AH$82,"",0),$G$32=$AF$84,_xlfn.XLOOKUP($J$32,$AG$84:$AG$88,AH84:AH88,"",0),$G$32=$AF$90,_xlfn.XLOOKUP($J$32,AG90:AG94,AH90:AH94,"",0),$G$32=AF96,_xlfn.XLOOKUP($J$32,AG96:AG100,AH96:AH100,"",0),$G$32=AF102,_xlfn.XLOOKUP(J32,AG102:AG106,AH102:AH106,"",0),$G$32=$AF$108,_xlfn.XLOOKUP($J$32,AG108:AG112,AH108:AH112,"",0),G32=AF114,_xlfn.XLOOKUP(J32,AG114:AG118,AH114:AH118,"",0),G32=AF120,_xlfn.XLOOKUP(J32,AG120:AG124,AH120:AH124,"",0),G32=AF126,_xlfn.XLOOKUP(J32,AG126:AG130,AH126:AH130,"",0),G32=AF132,_xlfn.XLOOKUP(J32,AG132:AG136,AH132:AH136,"",0),G32=AF138,_xlfn.XLOOKUP(J32,AG138:AG142,AH138:AH142,"",0),G32=AF144,_xlfn.XLOOKUP(J32,AG144:AG148,AH144:AH148,"",0),G32="","โปรดระบุเกณฑ์ความสามารถ")} -> มักพัฒนาเฉพาะทักษะที่จำเป็นต้องใช้ในการทำงาน | T32: Will fit | U32: 7 | V32: =$I$32 -> 2 | W32: =$J$32 -> 2 | X32: =IF($J$32<$I$32,1,IF($J$32=$I$32,2,3)) -> 2
C33: เกณฑ์ทักษะความสามารถที่คาดหวัง: | L33: ทีม: | T33: Total | V33: =SUM($V$26:$V$32) -> 15 | W33: =SUM($W$26:$W$32) -> 16 | X33: =SUM($X$26:$X$32) -> 15
C34: {=_xlfn.IFS($G$32=$AF$78,_xlfn.XLOOKUP($I$32,$AG$78:$AG$82,$AH$78:$AH$82,"",0),$G$32=$AF$84,_xlfn.XLOOKUP($I$32,$AG$84:$AG$88,AH84:AH88,"",0),$G$32=$AF$90,_xlfn.XLOOKUP($I$32,AG90:AG94,AH90:AH94,"",0),$G$32=AF96,_xlfn.XLOOKUP($I$32,AG96:AG100,AH96:AH100,"",0),$G$32=AF102,_xlfn.XLOOKUP(I32,AG102:AG106,AH102:AH106,"",0),$G$32=$AF$108,_xlfn.XLOOKUP($I$32,AG108:AG112,AH108:AH112,"",0),G32=AF114,_xlfn.XLOOKUP(I32,AG114:AG118,AH114:AH118,"",0),G32=AF120,_xlfn.XLOOKUP(I32,AG120:AG124,AH120:AH124,"",0),G32=AF126,_xlfn.XLOOKUP(I32,AG126:AG130,AH126:AH130,"",0),G32=AF132,_xlfn.XLOOKUP(I32,AG132:AG136,AH132:AH136,"",0),G32=AF138,_xlfn.XLOOKUP(I32,AG138:AG142,AH138:AH142,"",0),G32=AF144,_xlfn.XLOOKUP(I32,AG144:AG148,AH144:AH148,"",0),G32="","โปรดระบุเกณฑ์ความสามารถ")} -> มักพัฒนาเฉพาะทักษะที่จำเป็นต้องใช้ในการทำงาน
T35: ตัวช่วยเพื่อวางเงื่อนไขคำนวณคะแนนน Will do | U35: ตัวช่วยเพื่อวางเงื่อนไขคำนวณคะแนนน can do | V35: ตัวช่วยเพื่อวางเงื่อนไขคำนวณคะแนนน Will fit | W35: ตัวช่วยเพื่อวางเงื่อนคะแนนที่คาดหวัง | X35: ตัวช่วยเพื่อวางเงื่อนคะแนนการสัมภาษณ์
T36: =COUNTIFS($K$20:$K$27,"Below") -> 1 | U36: =COUNTIF($K$8:$K$19,"Below") -> 0 | V36: =COUNTIFS($K$28:$K$35,"Below") -> 0 | W36: สิ่งที่ต้องทำ (Can do) | X36: สิ่งที่ต้องทำ (Can do)
A37: จุดเด่น | J37: จุดด้อย | T37: =COUNTIF($K$20:$K$27,"Meet") -> 0 | U37: =COUNTIF($K$8:$K$19,"Meet") -> 3 | V37: =COUNTIFS($K$28:$K$35,"Meet") -> 1 | W37: =SUM($I$8:$I$19) -> 7 | X37: =SUM($J$8:$J$19) -> 7
T38: =COUNTIF($K$20:$K$27,"Exceed") -> 1 | U38: =COUNTIF($K$8:$K$19,"Exceed") -> 0 | V38: =COUNTIFS($K$28:$K$35,"Exceed") -> 1 | W38: แรงจูงใจ(Will do) | X38: แรงจูงใจ(Will do)
W39: =SUM($I$20:$I$27) -> 4 | X39: =SUM($J$20:$J$27) -> 4
W40: ความเหมาะสมกับวัฒนธรรม (Will fit) | X40: ความเหมาะสมกับวัฒนธรรม (Will fit)
W41: =SUM($I$28:$I$35) -> 4 | X41: =SUM($J$28:$J$35) -> 5
A42: เหตุผลในการขอเสนอจ้าง:
...

Sheet Evaluate Interview form (Demo)
A1: แบบประเมินการสัมภาษณ์งาน
A2: ชื่อ-นามสกุล: | G2: ตำแหน่งที่สมัคร (Positions): | M2: บทบาท (Role):
A3: บริษัท: | G3: ฝ่าย (Department): | M3: แผนก (Section):
A4: วันที่สัมภาษณ์: | G4: ผู้สัมภาษณ์ (Interviewer): | M4: ผู้สรรหา (Recruiter): | T4: Can do | U4: Eng Can do | V4: ความหมาย Can do | W4: Will do | X4: Eng Will do | Y4: ความหมาย Will do | Z4: Will fit | AA4: Eng Will fit | AB4: ความหมาย Will fit | AC4: Score
A5: บันทึกผลการสัมภาษณ์ | T5: การคิดวิเคราะห์ & การตัดสินใจ (Analytical Thinking & Decision Making) | U5: Analytical Thinking | V5: • ความสามารถในการวิเคราะห์ ประมวลข้อมูล และสรุปประเด็นสำคัญ • การวิเคราะห์และตัดสินใจบนพื้นฐานของข้อมูลอย่างสมเหตุสมผล | W5: การคิดเชิงวิเคราะห์ (Analytical Thinking) | X5: Analytical Thinking | Y5: • ความสามารถในการวิเคราะห์ ประมวลข้อมูล และสรุปประเด็นสำคัญ • การวิเคราะห์และตัดสินใจบนพื้นฐานของข้อมูลอย่างสมเหตุสมผล | Z5: พัฒนาทักษะตัวเองอยู่เสมอ (Self-Development) | AA5: Self-Development | AB5: • พฤติกรรมในการพัฒนาทักษะและความสามารถของตนเองอยู่เสมอ | AC5: 5
A6: หลักพิจารณา | B6: รายการประเมิน | G6: เลือกสมรรถนะที่ต้องการประเมิน | I6: คาดหวัง | J6: คะแนน | K6: ผลประเมิน | L6: หมายเหตุ/ ความคิดเห็น | T6: ความเชี่ยวชาญด้านเทคนิค (Technical Skill) | U6: Technical Skill | V6: • ทักษะด้านการเขียนโปรแกรมหรือเครื่องมื่อต่างๆ | W6: การแก้ไขปัญหา (Problem Solving) | X6: Problem Solving | Y6: • การวิเคราะห์สถานการณ์และการคิดอย่างเป็นระบบ • ความคิดสร้างสรรค์ในการหาทางออก | Z6: การปรับตัว & การทำงานร่วมกันเป็นทีม (Adaptability & Teamwork) | AA6: Teamwork & Adaptability | AB6: • สามารถปรับตัวทำงานร่วมกับทีมได้ดี • พร้อมรับฟังและยอมรับความเห็นต่าง | AC6: 4
A7: (Pillar) | B7: (List) | G7: (Competency) | I7: (Expect) | J7: (Score) | K7: (Result) | L7: (Note/ Comment) | T7: ความฉับไวในการเรียนรู้ (Learning Agility) | U7: Learning Agility | V7: • เรียนรู้เทคโนโลยีใหม่ ๆ ได้เร็วและต่อเนื่อง | W7: ความเชี่ยวชาญด้านเทคนิค (Technical Skill) | X7: Technical Skill | Y7: • ทักษะด้านการเขียนโปรแกรมหรือเครื่องมื่อต่างๆ | Z7: ทักษะการสื่อสารและเจรจา (Communication & Negotiation) | AA7: Communication & Negotiation | AB7: • สามารถในการอธิบายแนวคิด หรือ เรื่องราวต่างๆ ได้ชัดเจน | AC7: 3
A8: ที่ต้องทำ (Can do) | B8: 1 | C8: =IF(ISBLANK($G$8),"โปรดเลือกสมรรถนะที่ต้องการประเมิน",$G$8) -> การแก้ไขปัญหา (Problem Solving) | E8: *ทักษะความสามารถที่จำเป็น | G8: การแก้ไขปัญหา (Problem Solving) | I8: 2 | K8: =IF($J$8="","ระบุคะแนน",IF($J$8<$I$8,"Below",IF($J$8=$I$8,"Meet","Exceed"))) -> ระบุคะแนน | L8: ผล: | M8: {=_xlfn.IFS( $G$8=$AF$78,_xlfn.XLOOKUP($J$8,$AG$78:$AG$82,$AH$78:$AH$82,"",0), $G$8=$AF$84,_xlfn.XLOOKUP($J$8,$AG$84:$AG$88,$AH$84:$AH$88,"",0), $G$8=$AF$90,_xlfn.XLOOKUP($J$8,$AG$90:$AG$94,$AH$90:$AH$94,"",0), $G$8=$AF$96,_xlfn.XLOOKUP($J$8,$AG$96:$AG$100,$AH$96:$AH$100,"",0), $G$8=$AF$102,_xlfn.XLOOKUP($J$8,$AG$102:$AG$106,$AH$102:$AH$106,"",0), $G$8=$AF$108,_xlfn.XLOOKUP($J$8,$AG$108:$AG$112,$AH$108:$AH$112,"",0), $G$8=$AF$114,_xlfn.XLOOKUP($J$8,$AG$114:$AG$118,$AH$114:$AH$118,"",0), $G$8=$AF$120,_xlfn.XLOOKUP($J$8,$AG$120:$AG$124,$AH$120:$AH$124,"",0), $G$8=$AF$126,_xlfn.XLOOKUP($J$8,$AG$126:$AG$130,$AH$126:$AH$130,"",0), $G$8=$AF$132,_xlfn.XLOOKUP($J$8,$AG$132:$AG$136,$AH$132:$AH$136,"",0), $G$8=$AF$138,_xlfn.XLOOKUP($J$8,$AG$138:$AG$142,$AH$138:$AH$142,"",0), $G$8=$AF$144,_xlfn.XLOOKUP($J$8,$AG$144:$AG$148,$AH$144:$AH$148,"",0), $G$8=$AF$149,_xlfn.XLOOKUP($J$8,$AG$149:$AG$153,$AH$149:$AH$153,"",0), $G$8=$AF$155,_xlfn.XLOOKUP($J$8,$AG$155:$AG$159,$AH$155:$AH$159,"",0), $G$8=$AF$161,_xlfn.XLOOKUP($J$8,$AG$161:$AG$165,$AH$161:$AH$165,"",0), $G$8=$AF$167,_xlfn.XLOOKUP($J$8,$AG$167:$AG$171,$AH$167:$AH$171,"",0), $G$8=$AF$173,_xlfn.XLOOKUP($J$8,$AG$173:$AG$177,$AH$173:$AH$177,"",0), $G$8=$AF$180,_xlfn.XLOOKUP($J$8,$AG$180:$AG$184,$AH$180:$AH$184,"",0), $G$8=$AF$186,_xlfn.XLOOKUP($J$8,$AG$186:$AG$190,$AH$186:$AH$190,"",0), $G$16="","โปรดระบุเกณฑ์ความสามารถ" )} | T8: การวางแผนและการจัดระเบียบ (Planning & Organizing) | U8: Planning & Organizing | V8: • สามารถวางแผนการจัดการปัญหาหรือโปรเจกต์ได้อย่างมีประสิทธิภาพและลื่นไหล | W8: ความฉับไวในการเรียนรู้ (Learning Agility) | X8: Learning Agility | Y8: • เรียนรู้เทคโนโลยีใหม่ ๆ ได้เร็วและต่อเนื่อง | AC8: 2
C9: เกณฑ์ทักษะความสามารถที่คาดหวัง: | L9: ทีม: | T9: ทักษะการสื่อสารและเจรจา (Communication & Negotiation) | U9: Communication & Negotiation | V9: • สามารถในการอธิบายแนวคิด หรือ เรื่องราวต่างๆ ได้ชัดเจน • สามารถจูงใจหรือโน้วน้าวผู้อื่น ได้ | W9: การวางแผนและการจัดระเบียบ (Planning & Organizing) | X9: Planning & Organizing | Y9: • สามารถวางแผนการจัดการปัญหาหรือโปรเจกต์ได้อย่างมีประสิทธิภาพและลื่นไหล | Z9: มีความซื่อสัตย์ในการทำงาน (Work Ethic) | AA9: Work Ethic | AB9: • พฤติกรรมที่ซื่อตรงในการทำงาน ไม่ปกปิดข้อมูลใดที่อาจก่อให้เกิดความเสียหาย | AC9: 1
C10: {=_xlfn.IFS($G$8=$AF$78,_xlfn.XLOOKUP($I$8,$AG$78:$AG$82,$AH$78:$AH$82,"",0),$G$8=$AF$84,_xlfn.XLOOKUP($I$8,$AG$84:$AG$88,AH84:AH88,"",0),$G$8=$AF$90,_xlfn.XLOOKUP($I$8,AG90:AG94,AH90:AH94,"",0),$G$8=AF96,_xlfn.XLOOKUP(I8,AG96:AG100,AH96:AH100,"",0),$G$8=AF102,_xlfn.XLOOKUP(I8,AG102:AG106,AH102:AH106,"",0),$G$8=$AF$108,_xlfn.XLOOKUP(I8,AG108:AG112,AH108:AH112,"",0),G8=AF114,_xlfn.XLOOKUP(I8,AG114:AG118,AH114:AH118,"",0),G8=AF120,_xlfn.XLOOKUP(I8,AG120:AG124,AH120:AH124,"",0),G8=AF126,_xlfn.XLOOKUP(I8,AG126:AG130,AH126:AH130,"",0),G8=AF132,_xlfn.XLOOKUP(I8,AG132:AG136,AH132:AH136,"",0),G8=AF138,_xlfn.XLOOKUP(I8,AG138:AG142,AH138:AH142,"",0),G8=AF144,_xlfn.XLOOKUP(I8,AG144:AG148,AH144:AH148,"",0),G8=AF149,_xlfn.XLOOKUP(I8,AG149:AG153,AH149:AH153,"",0),G8=AF155,_xlfn.XLOOKUP(I8,AG155:AG159,AH155:AH159,"",0),G8=AF161,_xlfn.XLOOKUP(I8,AG161:AG165,AH161:AH165,"",0),G8=AF167,_xlfn.XLOOKUP(I8,AG167:AG171,AH167:AH171,"",0),G8=AF173,_xlfn.XLOOKUP(I8,AG173:AG177,AH173:AH177,"",0),G8=AF180,_xlfn.XLOOKUP(I8,AG180:AG184,AH180:AH184,"",0),G8=AF186,_xlfn.XLOOKUP(I8,AG186:AG190,AH186:AH190,"",0),G16="","โปรดระบุเกณฑ์ความสามารถ")} -> แก้ไขปัญหา โดยศึกษาข้อมูลพื้นฐาน / ถามผู้รู้ เช่น ไล่ code แก้ bug ง่ายเองได้ | T10: มีใจรักการบริการและพร้อมช่วยเหลือลูกค้า (Service Mindset) | U10: Service Mindset | V10: • ความตั้งใจ มุ่งมั่น ใส่ใจ และเต็มใจที่จะให้บริการลูกค้าอย่างดีที่สุด | W10: การจัดการเวลา (Time Management) | X10: Time Management | Y10: • สามารถบริหารเวลาในการทำงานได้อย่างเหมาะสม | Z10: เข้าใจและตอบสนองความต้องการ & ใจรักการบริการ (Customer Focus & Service Mindset) | AA10: Customer Focus | AB10: • สามารถรวบรวมข้อมูล วิเคราะห์ กระทั่งเข้าใจและตอบสนองความต้องการของลูกค้าอย่างแท้จริงอย่างเป็นมิตร
T11: การแก้ไขปัญหา (Problem Solving) | U11: Problem Solving | V11: • การวิเคราะห์สถานการณ์และการคิดอย่างเป็นระบบ • ความคิดสร้างสรรค์ในการหาทางออก | W11: ทักษะการสื่อสารและเจรจา (Communication & Negotiation) | X11: Communication & Negotiation | Y11: • สามารถในการอธิบายแนวคิด หรือ เรื่องราวต่างๆ ได้ชัดเจน • สามารถจูงใจหรือโน้วน้าวผู้อื่น ได้ | Z11: ความกระตือรือร้น & ทัศนคติเชิงบวก (Proactive & Growth Mindset) | AA11: Proactive & Growth Mindset | AB11: • ความกระตือรือร้นที่จะทำงาน หาความรู้ วิธีการรับมือกับปัญหา
B12: 2 | C12: =IF(ISBLANK($G$12),"โปรดเลือกสมรรถนะที่ต้องการประเมิน",$G$12) -> SQL Syntax (Basic) | G12: SQL Syntax (Basic) | I12: 2 | K12: =IF($J$12="","ระบุคะแนน",IF($J$12<$I$12,"Below",IF($J$12=$I$12,"Meet","Exceed"))) -> ระบุคะแนน | L12: ผล: | M12: {=_xlfn.IFS( $G$12=$AF$78,_xlfn.XLOOKUP($J$12,$AG$78:$AG$82,$AH$78:$AH$82,"",0), $G$12=$AF$84,_xlfn.XLOOKUP($J$12,$AG$84:$AG$88,$AH$84:$AH$88,"",0), $G$12=$AF$90,_xlfn.XLOOKUP($J$12,$AG$90:$AG$94,$AH$90:$AH$94,"",0), $G$12=$AF$96,_xlfn.XLOOKUP($J$12,$AG$96:$AG$100,$AH$96:$AH$100,"",0), $G$12=$AF$102,_xlfn.XLOOKUP($J$12,$AG$102:$AG$106,$AH$102:$AH$106,"",0), $G$12=$AF$108,_xlfn.XLOOKUP($J$12,$AG$108:$AG$112,$AH$108:$AH$112,"",0), $G$12=$AF$114,_xlfn.XLOOKUP($J$12,$AG$114:$AG$118,$AH$114:$AH$118,"",0), $G$12=$AF$120,_xlfn.XLOOKUP($J$12,$AG$120:$AG$124,$AH$120:$AH$124,"",0), $G$12=$AF$126,_xlfn.XLOOKUP($J$12,$AG$126:$AG$130,$AH$126:$AH$130,"",0), $G$12=$AF$132,_xlfn.XLOOKUP($J$12,$AG$132:$AG$136,$AH$132:$AH$136,"",0), $G$12=$AF$138,_xlfn.XLOOKUP($J$12,$AG$138:$AG$142,$AH$138:$AH$142,"",0), $G$12=$AF$144,_xlfn.XLOOKUP($J$12,$AG$144:$AG$148,$AH$144:$AH$148,"",0), $G$12=$AF$149,_xlfn.XLOOKUP($J$12,$AG$149:$AG$153,$AH$149:$AH$153,"",0), $G$12=$AF$155,_xlfn.XLOOKUP($J$12,$AG$155:$AG$159,$AH$155:$AH$159,"",0), $G$12=$AF$161,_xlfn.XLOOKUP($J$12,$AG$161:$AG$165,$AH$161:$AH$165,"",0), $G$12=$AF$167,_xlfn.XLOOKUP($J$12,$AG$167:$AG$171,$AH$167:$AH$171,"",0), $G$12=$AF$173,_xlfn.XLOOKUP($J$12,$AG$173:$AG$177,$AH$173:$AH$177,"",0), $G$12=$AF$180,_xlfn.XLOOKUP($J$12,$AG$180:$AG$184,$AH$180:$AH$184,"",0), $G$12=$AF$186,_xlfn.XLOOKUP($J$12,$AG$186:$AG$190,$AH$186:$AH$190,"",0), $G$12="","โปรดระบุเกณฑ์ความสามารถ" )} | W12: มุ่งมั่นให้งานเสร็จและมีคุณภาพ (Drive for Achievement) | X12: Drive for Achievement | Y12: • ผู้ที่มักตั้งเป้าหมายที่ชัดเจน และมุ่งมั่นอย่างสูงเพื่อให้งานเสร็จและมีคุณภาพ
C13: เกณฑ์ทักษะความสามารถที่คาดหวัง: | L13: ทีม: | W13: รับผิดชอบงานของตนเอง (Accountability / Ownership) | X13: Accountability / Ownership | Y13: • พฤติกรรมที่รับผิดชอบงานของตนเองให้เสร็จตามเวลาที่กำหนด
C14: {=_xlfn.IFS( $G$12=$AF$78,_xlfn.XLOOKUP($I$12,$AG$78:$AG$82,$AH$78:$AH$82,"",0), $G$12=$AF$84,_xlfn.XLOOKUP($I$12,$AG$84:$AG$88,$AH$84:$AH$88,"",0), $G$12=$AF$90,_xlfn.XLOOKUP($I$12,$AG$90:$AG$94,$AH$90:$AH$94,"",0), $G$12=$AF$96,_xlfn.XLOOKUP($I$12,$AG$96:$AG$100,$AH$96:$AH$100,"",0), $G$12=$AF$102,_xlfn.XLOOKUP($I$12,$AG$102:$AG$106,$AH$102:$AH$106,"",0), $G$12=$AF$108,_xlfn.XLOOKUP($I$12,$AG$108:$AG$112,$AH$108:$AH$112,"",0), $G$12=$AF$114,_xlfn.XLOOKUP($I$12,$AG$114:$AG$118,$AH$114:$AH$118,"",0), $G$12=$AF$120,_xlfn.XLOOKUP($I$12,$AG$120:$AG$124,$AH$120:$AH$124,"",0), $G$12=$AF$126,_xlfn.XLOOKUP($I$12,$AG$126:$AG$130,$AH$126:$AH$130,"",0), $G$12=$AF$132,_xlfn.XLOOKUP($I$12,$AG$132:$AG$136,$AH$132:$AH$136,"",0), $G$12=$AF$138,_xlfn.XLOOKUP($I$12,$AG$138:$AG$142,$AH$138:$AH$142,"",0), $G$12=$AF$144,_xlfn.XLOOKUP($I$12,$AG$144:$AG$148,$AH$144:$AH$148,"",0), $G$12=$AF$149,_xlfn.XLOOKUP($I$12,$AG$149:$AG$153,$AH$149:$AH$153,"",0), $G$12=$AF$155,_xlfn.XLOOKUP($I$12,$AG$155:$AG$159,$AH$155:$AH$159,"",0), $G$12=$AF$161,_xlfn.XLOOKUP($I$12,$AG$161:$AG$165,$AH$161:$AH$165,"",0), $G$12=$AF$167,_xlfn.XLOOKUP($I$12,$AG$167:$AG$171,$AH$167:$AH$171,"",0), $G$12=$AF$173,_xlfn.XLOOKUP($I$12,$AG$173:$AG$177,$AH$173:$AH$177,"",0), $G$12=$AF$180,_xlfn.XLOOKUP($I$12,$AG$180:$AG$184,$AH$180:$AH$184,"",0), $G$12=$AF$186,_xlfn.XLOOKUP($I$12,$AG$186:$AG$190,$AH$186:$AH$190,"",0), $G$16="","โปรดระบุเกณฑ์ความสามารถ" )} -> มีความรู้ระดับพื้นฐาน SQL เช่น สามารถใช้ SELECT, JOIN, WHERE, GROUP BY, INSERT, UPDATE, DELETE | W14: ความกระตือรือร้น & ทัศนคติเชิงบวก (Proactive & Growth Mindset) | X14: Proactive & Growth Mindset | Y14: • ความกระตือรือร้นที่จะทำงาน หาความรู้ วิธีการรับมือกับปัญหา
W15: พัฒนาทักษะตัวเองอยู่เสมอ (Self-Development) | X15: Self-Development | Y15: • พฤติกรรมในการพัฒนาทักษะและความสามารถของตนเองอยู่เสมอ
B16: 3 | C16: =IF(ISBLANK($G$16),"โปรดเลือกสมรรถนะที่ต้องการประเมิน",$G$16) -> ทักษะการสื่อสารและเจรจา (Communication & Negotiation) | G16: ทักษะการสื่อสารและเจรจา (Communication & Negotiation) | I16: 2 | K16: =IF($J$16="","ระบุคะแนน",IF($J$16<$I$16,"Below",IF($J$16=$I$16,"Meet","Exceed"))) -> ระบุคะแนน | L16: ผล: | M16: {=_xlfn.IFS( $G$16=$AF$78,_xlfn.XLOOKUP($J$16,$AG$78:$AG$82,$AH$78:$AH$82,"",0), $G$16=$AF$84,_xlfn.XLOOKUP($J$16,$AG$84:$AG$88,$AH$84:$AH$88,"",0), $G$16=$AF$90,_xlfn.XLOOKUP($J$16,$AG$90:$AG$94,$AH$90:$AH$94,"",0), $G$16=$AF$96,_xlfn.XLOOKUP($J$16,$AG$96:$AG$100,$AH$96:$AH$100,"",0), $G$16=$AF$102,_xlfn.XLOOKUP($J$16,$AG$102:$AG$106,$AH$102:$AH$106,"",0), $G$16=$AF$108,_xlfn.XLOOKUP($J$16,$AG$108:$AG$112,$AH$108:$AH$112,"",0), $G$16=$AF$114,_xlfn.XLOOKUP($J$16,$AG$114:$AG$118,$AH$114:$AH$118,"",0), $G$16=$AF$120,_xlfn.XLOOKUP($J$16,$AG$120:$AG$124,$AH$120:$AH$124,"",0), $G$16=$AF$126,_xlfn.XLOOKUP($J$16,$AG$126:$AG$130,$AH$126:$AH$130,"",0), $G$16=$AF$132,_xlfn.XLOOKUP($J$16,$AG$132:$AG$136,$AH$132:$AH$136,"",0), $G$16=$AF$138,_xlfn.XLOOKUP($J$16,$AG$138:$AG$142,$AH$138:$AH$142,"",0), $G$16=$AF$144,_xlfn.XLOOKUP($J$16,$AG$144:$AG$148,$AH$144:$AH$148,"",0), $G$16=$AF$149,_xlfn.XLOOKUP($J$16,$AG$149:$AG$153,$AH$149:$AH$153,"",0), $G$16=$AF$155,_xlfn.XLOOKUP($J$16,$AG$155:$AG$159,$AH$155:$AH$159,"",0), $G$16=$AF$161,_xlfn.XLOOKUP($J$16,$AG$161:$AG$165,$AH$161:$AH$165,"",0), $G$16=$AF$167,_xlfn.XLOOKUP($J$16,$AG$167:$AG$171,$AH$167:$AH$171,"",0), $G$16=$AF$173,_xlfn.XLOOKUP($J$16,$AG$173:$AG$177,$AH$173:$AH$177,"",0), $G$16=$AF$180,_xlfn.XLOOKUP($J$16,$AG$180:$AG$184,$AH$180:$AH$184,"",0), $G$16=$AF$186,_xlfn.XLOOKUP($J$16,$AG$186:$AG$190,$AH$186:$AH$190,"",0), $G$16="","โปรดระบุเกณฑ์ความสามารถ" )} | W16: เข้าใจและตอบสนองความต้องการ & ใจรักการบริการ (Customer Focus & Service Mindset) | X16: Customer Focus & Service Mindset | Y16: • สามารถรวบรวมข้อมูล วิเคราะห์ กระทั่งเข้าใจและตอบสนองความต้องการของลูกค้าอย่างแท้จริงอย่างเป็นมิตร
C17: เกณฑ์ทักษะความสามารถที่คาดหวัง: | L17: ทีม:
C18: {=_xlfn.IFS( $G$16=$AF$78,_xlfn.XLOOKUP($I$16,$AG$78:$AG$82,$AH$78:$AH$82,"",0), $G$16=$AF$84,_xlfn.XLOOKUP($I$16,$AG$84:$AG$88,$AH$84:$AH$88,"",0), $G$16=$AF$90,_xlfn.XLOOKUP($I$16,$AG$90:$AG$94,$AH$90:$AH$94,"",0), $G$16=$AF$96,_xlfn.XLOOKUP($I$16,$AG$96:$AG$100,$AH$96:$AH$100,"",0), $G$16=$AF$102,_xlfn.XLOOKUP($I$16,$AG$102:$AG$106,$AH$102:$AH$106,"",0), $G$16=$AF$108,_xlfn.XLOOKUP($I$16,$AG$108:$AG$112,$AH$108:$AH$112,"",0), $G$16=$AF$114,_xlfn.XLOOKUP($I$16,$AG$114:$AG$118,$AH$114:$AH$118,"",0), $G$16=$AF$120,_xlfn.XLOOKUP($I$16,$AG$120:$AG$124,$AH$120:$AH$124,"",0), $G$16=$AF$126,_xlfn.XLOOKUP($I$16,$AG$126:$AG$130,$AH$126:$AH$130,"",0), $G$16=$AF$132,_xlfn.XLOOKUP($I$16,$AG$132:$AG$136,$AH$132:$AH$136,"",0), $G$16=$AF$138,_xlfn.XLOOKUP($I$16,$AG$138:$AG$142,$AH$138:$AH$142,"",0), $G$16=$AF$144,_xlfn.XLOOKUP($I$16,$AG$144:$AG$148,$AH$144:$AH$148,"",0), $G$16=$AF$149,_xlfn.XLOOKUP($I$16,$AG$149:$AG$153,$AH$149:$AH$153,"",0), $G$16=$AF$155,_xlfn.XLOOKUP($I$16,$AG$155:$AG$159,$AH$155:$AH$159,"",0), $G$16=$AF$161,_xlfn.XLOOKUP($I$16,$AG$161:$AG$165,$AH$161:$AH$165,"",0), $G$16=$AF$167,_xlfn.XLOOKUP($I$16,$AG$167:$AG$171,$AH$167:$AH$171,"",0), $G$16=$AF$173,_xlfn.XLOOKUP($I$16,$AG$173:$AG$177,$AH$173:$AH$177,"",0), $G$16=$AF$180,_xlfn.XLOOKUP($I$16,$AG$180:$AG$184,$AH$180:$AH$184,"",0), $G$16=$AF$186,_xlfn.XLOOKUP($I$16,$AG$186:$AG$190,$AH$186:$AH$190,"",0), $G$16="","โปรดระบุเกณฑ์ความสามารถ" )} -> สื่อสารรู้เรื่อง เช่น เข้าใจเนื่อหาที่ผู้สมัครต้องการสื่อสาร
A20: ที่ชอบทำ (Will do) | B20: 4 | C20: =IF(ISBLANK($G$20),"โปรดเลือกสมรรถนะที่ต้องการประเมิน",$G$20) -> ความฉับไวในการเรียนรู้ (Learning Agility) | G20: ความฉับไวในการเรียนรู้ (Learning Agility) | I20: 2 | K20: =IF($J$20="","ระบุคะแนน",IF($J$20<$I$20,"Below",IF($J$20=$I$20,"Meet","Exceed"))) -> ระบุคะแนน | L20: ผล: | M20: {=_xlfn.IFS( $G$8=$AF$78,_xlfn.XLOOKUP($J$20,$AG$78:$AG$82,$AH$78:$AH$82,"",0), $G$8=$AF$84,_xlfn.XLOOKUP($J$20,$AG$84:$AG$88,$AH$84:$AH$88,"",0), $G$8=$AF$90,_xlfn.XLOOKUP($J$20,$AG$90:$AG$94,$AH$90:$AH$94,"",0), $G$8=$AF$96,_xlfn.XLOOKUP($J$20,$AG$96:$AG$100,$AH$96:$AH$100,"",0), $G$8=$AF$102,_xlfn.XLOOKUP($J$20,$AG$102:$AG$106,$AH$102:$AH$106,"",0), $G$8=$AF$108,_xlfn.XLOOKUP($J$20,$AG$108:$AG$112,$AH$108:$AH$112,"",0), $G$8=$AF$114,_xlfn.XLOOKUP($J$20,$AG$114:$AG$118,$AH$114:$AH$118,"",0), $G$8=$AF$120,_xlfn.XLOOKUP($J$20,$AG$120:$AG$124,$AH$120:$AH$124,"",0), $G$8=$AF$126,_xlfn.XLOOKUP($J$20,$AG$126:$AG$130,$AH$126:$AH$130,"",0), $G$8=$AF$132,_xlfn.XLOOKUP($J$20,$AG$132:$AG$136,$AH$132:$AH$136,"",0), $G$8=$AF$138,_xlfn.XLOOKUP($J$20,$AG$138:$AG$142,$AH$138:$AH$142,"",0), $G$8=$AF$144,_xlfn.XLOOKUP($J$20,$AG$144:$AG$148,$AH$144:$AH$148,"",0), $G$8=$AF$149,_xlfn.XLOOKUP($J$20,$AG$149:$AG$153,$AH$149:$AH$153,"",0), $G$8=$AF$155,_xlfn.XLOOKUP($J$20,$AG$155:$AG$159,$AH$155:$AH$159,"",0), $G$8=$AF$161,_xlfn.XLOOKUP($J$20,$AG$161:$AG$165,$AH$161:$AH$165,"",0), $G$8=$AF$167,_xlfn.XLOOKUP($J$20,$AG$167:$AG$171,$AH$167:$AH$171,"",0), $G$8=$AF$173,_xlfn.XLOOKUP($J$20,$AG$173:$AG$177,$AH$173:$AH$177,"",0), $G$8=$AF$180,_xlfn.XLOOKUP($J$20,$AG$180:$AG$184,$AH$180:$AH$184,"",0), $G$8=$AF$186,_xlfn.XLOOKUP($J$20,$AG$186:$AG$190,$AH$186:$AH$190,"",0), $G$20="","โปรดระบุเกณฑ์ความสามารถ" )}
C21: เกณฑ์ทักษะความสามารถที่คาดหวัง: | L21: ทีม:
C22: {=_xlfn.IFS( $G$20=$AF$78,_xlfn.XLOOKUP($I$20,$AG$78:$AG$82,$AH$78:$AH$82,"",0), $G$20=$AF$84,_xlfn.XLOOKUP($I$20,$AG$84:$AG$88,$AH$84:$AH$88,"",0), $G$20=$AF$90,_xlfn.XLOOKUP($I$20,$AG$90:$AG$94,$AH$90:$AH$94,"",0), $G$20=$AF$96,_xlfn.XLOOKUP($I$20,$AG$96:$AG$100,$AH$96:$AH$100,"",0), $G$20=$AF$102,_xlfn.XLOOKUP($I$20,$AG$102:$AG$106,$AH$102:$AH$106,"",0), $G$20=$AF$108,_xlfn.XLOOKUP($I$20,$AG$108:$AG$112,$AH$108:$AH$112,"",0), $G$20=$AF$114,_xlfn.XLOOKUP($I$20,$AG$114:$AG$118,$AH$114:$AH$118,"",0), $G$20=$AF$120,_xlfn.XLOOKUP($I$20,$AG$120:$AG$124,$AH$120:$AH$124,"",0), $G$20=$AF$126,_xlfn.XLOOKUP($I$20,$AG$126:$AG$130,$AH$126:$AH$130,"",0), $G$20=$AF$132,_xlfn.XLOOKUP($I$20,$AG$132:$AG$136,$AH$132:$AH$136,"",0), $G$20=$AF$138,_xlfn.XLOOKUP($I$20,$AG$138:$AG$142,$AH$138:$AH$142,"",0), $G$20=$AF$144,_xlfn.XLOOKUP($I$20,$AG$144:$AG$148,$AH$144:$AH$148,"",0), $G$20=$AF$149,_xlfn.XLOOKUP($I$20,$AG$149:$AG$153,$AH$149:$AH$153,"",0), $G$20=$AF$155,_xlfn.XLOOKUP($I$20,$AG$155:$AG$159,$AH$155:$AH$159,"",0), $G$20=$AF$161,_xlfn.XLOOKUP($I$20,$AG$161:$AG$165,$AH$161:$AH$165,"",0), $G$20=$AF$167,_xlfn.XLOOKUP($I$20,$AG$167:$AG$171,$AH$167:$AH$171,"",0), $G$20=$AF$173,_xlfn.XLOOKUP($I$20,$AG$173:$AG$177,$AH$173:$AH$177,"",0), $G$20=$AF$180,_xlfn.XLOOKUP($I$20,$AG$180:$AG$184,$AH$180:$AH$184,"",0), $G$20=$AF$186,_xlfn.XLOOKUP($I$20,$AG$186:$AG$190,$AH$186:$AH$190,"",0), $G$16="","โปรดระบุเกณฑ์ความสามารถ" )} -> 1. ใช้เวลาในการเรียนรู้ /ทำความเข้าใจในเรื่องง่ายได้ 2. สามารถปรับใช้ได้ภายในเวลาที่เหมาะสม
B24: 5 | C24: =IF(ISBLANK($G$24),"โปรดเลือกสมรรถนะที่ต้องการประเมิน",$G$24) -> รับผิดชอบงานของตนเอง (Accountability / Ownership) | G24: รับผิดชอบงานของตนเอง (Accountability / Ownership) | I24: 2 | K24: =IF($J$24="","ระบุคะแนน",IF($J$24<$I$24,"Below",IF($J$24=$I$24,"Meet","Exceed"))) -> ระบุคะแนน | L24: ผล: | M24: {=_xlfn.IFS( $G$24=$AF$78,_xlfn.XLOOKUP($J$24,$AG$78:$AG$82,$AH$78:$AH$82,"",0), $G$24=$AF$84,_xlfn.XLOOKUP($J$24,$AG$84:$AG$88,$AH$84:$AH$88,"",0), $G$24=$AF$90,_xlfn.XLOOKUP($J$24,$AG$90:$AG$94,$AH$90:$AH$94,"",0), $G$24=$AF$96,_xlfn.XLOOKUP($J$24,$AG$96:$AG$100,$AH$96:$AH$100,"",0), $G$24=$AF$102,_xlfn.XLOOKUP($J$24,$AG$102:$AG$106,$AH$102:$AH$106,"",0), $G$24=$AF$108,_xlfn.XLOOKUP($J$24,$AG$108:$AG$112,$AH$108:$AH$112,"",0), $G$24=$AF$114,_xlfn.XLOOKUP($J$24,$AG$114:$AG$118,$AH$114:$AH$118,"",0), $G$24=$AF$120,_xlfn.XLOOKUP($J$24,$AG$120:$AG$124,$AH$120:$AH$124,"",0), $G$24=$AF$126,_xlfn.XLOOKUP($J$24,$AG$126:$AG$130,$AH$126:$AH$130,"",0), $G$24=$AF$132,_xlfn.XLOOKUP($J$24,$AG$132:$AG$136,$AH$132:$AH$136,"",0), $G$24=$AF$138,_xlfn.XLOOKUP($J$24,$AG$138:$AG$142,$AH$138:$AH$142,"",0), $G$24=$AF$144,_xlfn.XLOOKUP($J$24,$AG$144:$AG$148,$AH$144:$AH$148,"",0), $G$24=$AF$149,_xlfn.XLOOKUP($J$24,$AG$149:$AG$153,$AH$149:$AH$153,"",0), $G$24=$AF$155,_xlfn.XLOOKUP($J$24,$AG$155:$AG$159,$AH$155:$AH$159,"",0), $G$24=$AF$161,_xlfn.XLOOKUP($J$24,$AG$161:$AG$165,$AH$161:$AH$165,"",0), $G$24=$AF$167,_xlfn.XLOOKUP($J$24,$AG$167:$AG$171,$AH$167:$AH$171,"",0), $G$24=$AF$173,_xlfn.XLOOKUP($J$24,$AG$173:$AG$177,$AH$173:$AH$177,"",0), $G$24=$AF$180,_xlfn.XLOOKUP($J$24,$AG$180:$AG$184,$AH$180:$AH$184,"",0), $G$24=$AF$186,_xlfn.XLOOKUP($J$24,$AG$186:$AG$190,$AH$186:$AH$190,"",0), $G$24="","โปรดระบุเกณฑ์ความสามารถ" )}
C25: เกณฑ์ทักษะความสามารถที่คาดหวัง: | L25: ทีม: | T25: Part | U25: No | V25: Expect score | W25: Score | X25: Result | Y25: Interpreting | Z25: Can do, Best fit ,Cann't do, Not fit
C26: {=_xlfn.IFS( $G$24=$AF$78,_xlfn.XLOOKUP($I$24,$AG$78:$AG$82,$AH$78:$AH$82,"",0), $G$24=$AF$84,_xlfn.XLOOKUP($I$24,$AG$84:$AG$88,$AH$84:$AH$88,"",0), $G$24=$AF$90,_xlfn.XLOOKUP($I$24,$AG$90:$AG$94,$AH$90:$AH$94,"",0), $G$24=$AF$96,_xlfn.XLOOKUP($I$24,$AG$96:$AG$100,$AH$96:$AH$100,"",0), $G$24=$AF$102,_xlfn.XLOOKUP($I$24,$AG$102:$AG$106,$AH$102:$AH$106,"",0), $G$24=$AF$108,_xlfn.XLOOKUP($I$24,$AG$108:$AG$112,$AH$108:$AH$112,"",0), $G$24=$AF$114,_xlfn.XLOOKUP($I$24,$AG$114:$AG$118,$AH$114:$AH$118,"",0), $G$24=$AF$120,_xlfn.XLOOKUP($I$24,$AG$120:$AG$124,$AH$120:$AH$124,"",0), $G$24=$AF$126,_xlfn.XLOOKUP($I$24,$AG$126:$AG$130,$AH$126:$AH$130,"",0), $G$24=$AF$132,_xlfn.XLOOKUP($I$24,$AG$132:$AG$136,$AH$132:$AH$136,"",0), $G$24=$AF$138,_xlfn.XLOOKUP($I$24,$AG$138:$AG$142,$AH$138:$AH$142,"",0), $G$24=$AF$144,_xlfn.XLOOKUP($I$24,$AG$144:$AG$148,$AH$144:$AH$148,"",0), $G$24=$AF$149,_xlfn.XLOOKUP($I$24,$AG$149:$AG$153,$AH$149:$AH$153,"",0), $G$24=$AF$155,_xlfn.XLOOKUP($I$24,$AG$155:$AG$159,$AH$155:$AH$159,"",0), $G$24=$AF$161,_xlfn.XLOOKUP($I$24,$AG$161:$AG$165,$AH$161:$AH$165,"",0), $G$24=$AF$167,_xlfn.XLOOKUP($I$24,$AG$167:$AG$171,$AH$167:$AH$171,"",0), $G$24=$AF$173,_xlfn.XLOOKUP($I$24,$AG$173:$AG$177,$AH$173:$AH$177,"",0), $G$24=$AF$180,_xlfn.XLOOKUP($I$24,$AG$180:$AG$184,$AH$180:$AH$184,"",0), $G$24=$AF$186,_xlfn.XLOOKUP($I$24,$AG$186:$AG$190,$AH$186:$AH$190,"",0), $G$24="","โปรดระบุเกณฑ์ความสามารถ" )} -> 1. รับผิดชอบงานที่รับมอบหมาย 2. มุ่งมั่นงานให้มีคุณภาพ 3. ให้ความสำคัญกับเวลา | T26: Can do | U26: 1 | V26: =$I$8 -> 2 | W26: =$J$8 -> 0 | X26: =IF($J$8<$I$8,1,IF($J$8=$I$8,2,3)) -> 1
T27: Can do | U27: 2 | V27: =$I$12 -> 2 | W27: =$J$12 -> 0 | X27: =IF($J$12<$I$12,1,IF($J$12=$I$12,2,3)) -> 1
A28: ที่เหมาะสม (Will fit) | B28: 6 | C28: =IF(ISBLANK($G$28),"โปรดเลือกสมรรถนะที่ต้องการประเมิน",$G$28) -> การปรับตัว & การทำงานร่วมกันเป็นทีม (Adaptability & Teamwork) | G28: การปรับตัว & การทำงานร่วมกันเป็นทีม (Adaptability & Teamwork) | I28: 2 | K28: =IF($J$28="","ระบุคะแนน",IF($J$28<$I$28,"Below",IF($J$28=$I$28,"Meet","Exceed"))) -> ระบุคะแนน | L28: ผล: | M28: {=_xlfn.IFS( $G$28=$AF$78,_xlfn.XLOOKUP($J$28,$AG$78:$AG$82,$AH$78:$AH$82,"",0), $G$28=$AF$84,_xlfn.XLOOKUP($J$28,$AG$84:$AG$88,$AH$84:$AH$88,"",0), $G$28=$AF$90,_xlfn.XLOOKUP($J$28,$AG$90:$AG$94,$AH$90:$AH$94,"",0), $G$28=$AF$96,_xlfn.XLOOKUP($J$28,$AG$96:$AG$100,$AH$96:$AH$100,"",0), $G$28=$AF$102,_xlfn.XLOOKUP($J$28,$AG$102:$AG$106,$AH$102:$AH$106,"",0), $G$28=$AF$108,_xlfn.XLOOKUP($J$28,$AG$108:$AG$112,$AH$108:$AH$112,"",0), $G$28=$AF$114,_xlfn.XLOOKUP($J$28,$AG$114:$AG$118,$AH$114:$AH$118,"",0), $G$28=$AF$120,_xlfn.XLOOKUP($J$28,$AG$120:$AG$124,$AH$120:$AH$124,"",0), $G$28=$AF$126,_xlfn.XLOOKUP($J$28,$AG$126:$AG$130,$AH$126:$AH$130,"",0), $G$28=$AF$132,_xlfn.XLOOKUP($J$28,$AG$132:$AG$136,$AH$132:$AH$136,"",0), $G$28=$AF$138,_xlfn.XLOOKUP($J$28,$AG$138:$AG$142,$AH$138:$AH$142,"",0), $G$28=$AF$144,_xlfn.XLOOKUP($J$28,$AG$144:$AG$148,$AH$144:$AH$148,"",0), $G$28=$AF$149,_xlfn.XLOOKUP($J$28,$AG$149:$AG$153,$AH$149:$AH$153,"",0), $G$28=$AF$155,_xlfn.XLOOKUP($J$28,$AG$155:$AG$159,$AH$155:$AH$159,"",0), $G$28=$AF$161,_xlfn.XLOOKUP($J$28,$AG$161:$AG$165,$AH$161:$AH$165,"",0), $G$28=$AF$167,_xlfn.XLOOKUP($J$28,$AG$167:$AG$171,$AH$167:$AH$171,"",0), $G$28=$AF$173,_xlfn.XLOOKUP($J$28,$AG$173:$AG$177,$AH$173:$AH$177,"",0), $G$28=$AF$180,_xlfn.XLOOKUP($J$28,$AG$180:$AG$184,$AH$180:$AH$184,"",0), $G$28=$AF$186,_xlfn.XLOOKUP($J$28,$AG$186:$AG$190,$AH$186:$AH$190,"",0), $G$28="","โปรดระบุเกณฑ์ความสามารถ" )} | T28: Can do | U28: 3 | V28: =$I$16 -> 2 | W28: =$J$16 -> 0 | X28: =IF($J$16<$I$16,1,IF($J$16=$I$16,2,3)) -> 1
C29: เกณฑ์ทักษะความสามารถที่คาดหวัง: | L29: ทีม: | T29: Will do | U29: 4 | V29: =$I$20 -> 2 | W29: =$J$20 -> 0 | X29: =IF($J$20<$I$20,1,IF($J$20=$I$20,2,3)) -> 1
C30: {=_xlfn.IFS( $G$28=$AF$78,_xlfn.XLOOKUP($I$28,$AG$78:$AG$82,$AH$78:$AH$82,"",0), $G$28=$AF$84,_xlfn.XLOOKUP($I$28,$AG$84:$AG$88,$AH$84:$AH$88,"",0), $G$28=$AF$90,_xlfn.XLOOKUP($I$28,$AG$90:$AG$94,$AH$90:$AH$94,"",0), $G$28=$AF$96,_xlfn.XLOOKUP($I$28,$AG$96:$AG$100,$AH$96:$AH$100,"",0), $G$28=$AF$102,_xlfn.XLOOKUP($I$28,$AG$102:$AG$106,$AH$102:$AH$106,"",0), $G$28=$AF$108,_xlfn.XLOOKUP($I$28,$AG$108:$AG$112,$AH$108:$AH$112,"",0), $G$28=$AF$114,_xlfn.XLOOKUP($I$28,$AG$114:$AG$118,$AH$114:$AH$118,"",0), $G$28=$AF$120,_xlfn.XLOOKUP($I$28,$AG$120:$AG$124,$AH$120:$AH$124,"",0), $G$28=$AF$126,_xlfn.XLOOKUP($I$28,$AG$126:$AG$130,$AH$126:$AH$130,"",0), $G$28=$AF$132,_xlfn.XLOOKUP($I$28,$AG$132:$AG$136,$AH$132:$AH$136,"",0), $G$28=$AF$138,_xlfn.XLOOKUP($I$28,$AG$138:$AG$142,$AH$138:$AH$142,"",0), $G$28=$AF$144,_xlfn.XLOOKUP($I$28,$AG$144:$AG$148,$AH$144:$AH$148,"",0), $G$28=$AF$149,_xlfn.XLOOKUP($I$28,$AG$149:$AG$153,$AH$149:$AH$153,"",0), $G$28=$AF$155,_xlfn.XLOOKUP($I$28,$AG$155:$AG$159,$AH$155:$AH$159,"",0), $G$28=$AF$161,_xlfn.XLOOKUP($I$28,$AG$161:$AG$165,$AH$161:$AH$165,"",0), $G$28=$AF$167,_xlfn.XLOOKUP($I$28,$AG$167:$AG$171,$AH$167:$AH$171,"",0), $G$28=$AF$173,_xlfn.XLOOKUP($I$28,$AG$173:$AG$177,$AH$173:$AH$177,"",0), $G$28=$AF$180,_xlfn.XLOOKUP($I$28,$AG$180:$AG$184,$AH$180:$AH$184,"",0), $G$28=$AF$186,_xlfn.XLOOKUP($I$28,$AG$186:$AG$190,$AH$186:$AH$190,"",0), $G$28="","โปรดระบุเกณฑ์ความสามารถ" )} -> รับฟังความคิดเห็น แต่ยังยึดตนเป็นศุนย์กลางอยู่บ้าง/ ทัศนคติไม่ตรงกัน/ ตรรกะในการคิดแตกต่างกันอยู่บ้าง | T30: Will do | U30: 5 | V30: =$I$24 -> 2 | W30: =$J$24 -> 0 | X30: =IF($J$24<$I$24,1,IF($J$24=$I$24,2,3)) -> 1
T31: Will fit | U31: 6 | V31: =$I$28 -> 2 | W31: =$J$28 -> 0 | X31: =IF($J$28<$I$28,1,IF($J$28=$I$28,2,3)) -> 1
B32: 7 | C32: =IF(ISBLANK($G$32),"โปรดเลือกสมรรถนะที่ต้องการประเมิน",$G$32) -> ความกระตือรือร้น & ทัศนคติเชิงบวก (Proactive & Growth Mindset) | G32: ความกระตือรือร้น & ทัศนคติเชิงบวก (Proactive & Growth Mindset) | I32: 2 | K32: =IF($J$32="","ระบุคะแนน",IF($J$32<$I$32,"Below",IF($J$32=$I$32,"Meet","Exceed"))) -> ระบุคะแนน | L32: ผล: | M32: {=_xlfn.IFS( $G$32=$AF$78,_xlfn.XLOOKUP($J$32,$AG$78:$AG$82,$AH$78:$AH$82,"",0), $G$32=$AF$84,_xlfn.XLOOKUP($J$32,$AG$84:$AG$88,$AH$84:$AH$88,"",0), $G$32=$AF$90,_xlfn.XLOOKUP($J$32,$AG$90:$AG$94,$AH$90:$AH$94,"",0), $G$32=$AF$96,_xlfn.XLOOKUP($J$32,$AG$96:$AG$100,$AH$96:$AH$100,"",0), $G$32=$AF$102,_xlfn.XLOOKUP($J$32,$AG$102:$AG$106,$AH$102:$AH$106,"",0), $G$32=$AF$108,_xlfn.XLOOKUP($J$32,$AG$108:$AG$112,$AH$108:$AH$112,"",0), $G$32=$AF$114,_xlfn.XLOOKUP($J$32,$AG$114:$AG$118,$AH$114:$AH$118,"",0), $G$32=$AF$120,_xlfn.XLOOKUP($J$32,$AG$120:$AG$124,$AH$120:$AH$124,"",0), $G$32=$AF$126,_xlfn.XLOOKUP($J$32,$AG$126:$AG$130,$AH$126:$AH$130,"",0), $G$32=$AF$132,_xlfn.XLOOKUP($J$32,$AG$132:$AG$136,$AH$132:$AH$136,"",0), $G$32=$AF$138,_xlfn.XLOOKUP($J$32,$AG$138:$AG$142,$AH$138:$AH$142,"",0), $G$32=$AF$144,_xlfn.XLOOKUP($J$32,$AG$144:$AG$148,$AH$144:$AH$148,"",0), $G$32=$AF$149,_xlfn.XLOOKUP($J$32,$AG$149:$AG$153,$AH$149:$AH$153,"",0), $G$32=$AF$155,_xlfn.XLOOKUP($J$32,$AG$155:$AG$159,$AH$155:$AH$159,"",0), $G$32=$AF$161,_xlfn.XLOOKUP($J$32,$AG$161:$AG$165,$AH$161:$AH$165,"",0), $G$32=$AF$167,_xlfn.XLOOKUP($J$32,$AG$167:$AG$171,$AH$167:$AH$171,"",0), $G$32=$AF$173,_xlfn.XLOOKUP($J$32,$AG$173:$AG$177,$AH$173:$AH$177,"",0), $G$32=$AF$180,_xlfn.XLOOKUP($J$32,$AG$180:$AG$184,$AH$180:$AH$184,"",0), $G$32=$AF$186,_xlfn.XLOOKUP($J$32,$AG$186:$AG$190,$AH$186:$AH$190,"",0), $G$32="","โปรดระบุเกณฑ์ความสามารถ" )} | T32: Will fit | U32: 7 | V32: =$I$32 -> 2 | W32: =$J$32 -> 0 | X32: =IF($J$32<$I$32,1,IF($J$32=$I$32,2,3)) -> 1
C33: เกณฑ์ทักษะความสามารถที่คาดหวัง: | L33: ทีม: | T33: Total | V33: =SUM($V$26:$V$32) -> 14 | W33: =SUM($W$26:$W$32) -> 0 | X33: =SUM($X$26:$X$32) -> 7
C34: {=_xlfn.IFS( $G$32=$AF$78,_xlfn.XLOOKUP($I$32,$AG$78:$AG$82,$AH$78:$AH$82,"",0), $G$32=$AF$84,_xlfn.XLOOKUP($I$32,$AG$84:$AG$88,$AH$84:$AH$88,"",0), $G$32=$AF$90,_xlfn.XLOOKUP($I$32,$AG$90:$AG$94,$AH$90:$AH$94,"",0), $G$32=$AF$96,_xlfn.XLOOKUP($I$32,$AG$96:$AG$100,$AH$96:$AH$100,"",0), $G$32=$AF$102,_xlfn.XLOOKUP($I$32,$AG$102:$AG$106,$AH$102:$AH$106,"",0), $G$32=$AF$108,_xlfn.XLOOKUP($I$32,$AG$108:$AG$112,$AH$108:$AH$112,"",0), $G$32=$AF$114,_xlfn.XLOOKUP($I$32,$AG$114:$AG$118,$AH$114:$AH$118,"",0), $G$32=$AF$120,_xlfn.XLOOKUP($I$32,$AG$120:$AG$124,$AH$120:$AH$124,"",0), $G$32=$AF$126,_xlfn.XLOOKUP($I$32,$AG$126:$AG$130,$AH$126:$AH$130,"",0), $G$32=$AF$132,_xlfn.XLOOKUP($I$32,$AG$132:$AG$136,$AH$132:$AH$136,"",0), $G$32=$AF$138,_xlfn.XLOOKUP($I$32,$AG$138:$AG$142,$AH$138:$AH$142,"",0), $G$32=$AF$144,_xlfn.XLOOKUP($I$32,$AG$144:$AG$148,$AH$144:$AH$148,"",0), $G$32=$AF$149,_xlfn.XLOOKUP($I$32,$AG$149:$AG$153,$AH$149:$AH$153,"",0), $G$32=$AF$155,_xlfn.XLOOKUP($I$32,$AG$155:$AG$159,$AH$155:$AH$159,"",0), $G$32=$AF$161,_xlfn.XLOOKUP($I$32,$AG$161:$AG$165,$AH$161:$AH$165,"",0), $G$32=$AF$167,_xlfn.XLOOKUP($I$32,$AG$167:$AG$171,$AH$167:$AH$171,"",0), $G$32=$AF$173,_xlfn.XLOOKUP($I$32,$AG$173:$AG$177,$AH$173:$AH$177,"",0), $G$32=$AF$180,_xlfn.XLOOKUP($I$32,$AG$180:$AG$184,$AH$180:$AH$184,"",0), $G$32=$AF$186,_xlfn.XLOOKUP($I$32,$AG$186:$AG$190,$AH$186:$AH$190,"",0), $G$32="","โปรดระบุเกณฑ์ความสามารถ" )} -> กระตือรือร้นเฉพาะในช่วงใกล้ส่งงาน/ เฉพาะช่วงที่จำเป็น
T35: ตัวช่วยเพื่อวางเงื่อนไขคำนวณคะแนนน Will do | U35: ตัวช่วยเพื่อวางเงื่อนไขคำนวณคะแนนน can do | V35: ตัวช่วยเพื่อวางเงื่อนไขคำนวณคะแนนน Will fit | W35: ตัวช่วยเพื่อวางเงื่อนคะแนนที่คาดหวัง | X35: ตัวช่วยเพื่อวางเงื่อนคะแนนการสัมภาษณ์
T36: =COUNTIFS($K$20:$K$27,"Below") -> 0 | U36: =COUNTIF($K$8:$K$19,"Below") -> 0 | V36: =COUNTIFS($K$28:$K$35,"Below") -> 0 | W36: สิ่งที่ต้องทำ (Can do) | X36: สิ่งที่ต้องทำ (Can do)
A37: จุดเด่น | J37: จุดด้อย | T37: =COUNTIF($K$20:$K$27,"Meet") -> 0 | U37: =COUNTIF($K$8:$K$19,"Meet") -> 0 | V37: =COUNTIFS($K$28:$K$35,"Meet") -> 0 | W37: =SUM($I$8:$I$19) -> 6 | X37: =SUM($J$8:$J$19) -> 0
T38: =COUNTIF($K$20:$K$27,"Exceed") -> 0 | U38: =COUNTIF($K$8:$K$19,"Exceed") -> 0 | V38: =COUNTIFS($K$28:$K$35,"Exceed") -> 0 | W38: แรงจูงใจ(Will do) | X38: แรงจูงใจ(Will do)
W39: =SUM($I$20:$I$27) -> 4 | X39: =SUM($J$20:$J$27) -> 0
W40: ความเหมาะสมกับวัฒนธรรม (Will fit) | X40: ความเหมาะสมกับวัฒนธรรม (Will fit)
W41: =SUM($I$28:$I$35) -> 4 | X41: =SUM($J$28:$J$35) -> 0
A42: เหตุผลในการขอเสนอจ้าง:
...

Sheet New_Competency Test 
A1: ข้อ | B1: สมรรถนะหลัก | C1: ระดับ | D1: พฤติกรรมขณะสัมภาษณ์ | E1: ทีมตรวจสอบและแก้ไข | F1: สรุป ความคาดหวัง
A2: 1 | B2: ='Evaluate Interview form'!$T$5 -> การคิดวิเคราะห์ & การตัดสินใจ (Analytical Thinking & Decision Making) | C2: 1 | D2: ไม่ตัดสินใจ /ไม่สามารถคิดวิเคราะห์ได้ เช่น วิเคราะห์หาสาเหตุไม่ได้
B3: • ความสามารถตัดสินใจอย่างมีเหตุผล โดยผ่านการวิเคราะห์ ประมวลข้อมูล และสรุปประเด็นสำคัญ | C3: 2 | D3: 1. สามารถวิเคราะห์ข้อมูลเบื้องต้น 2.ตัดสินใจได้อย่างสมเหตุสมผลภายใต้พื้นฐานของข้อมูล
B4: • การคิดจำแนกแจกแจงองค์ประกอบต่างๆ ของปัญหาออกเป็นประเด็นย่อยๆ ในหลายๆแง่มุม แล้วนำมาวิเคราะห์และเชื่อมโยง | C4: 3 | D4: 1. สามารถวิเคราะห์แบบเจาะจงรายละเอียด 2. แยกแยะและเชื่อมโยงได้ 3. ถูกต้องตามพื้นฐานข้อมูล 4. ตัดสินใจได้สมเหตุสมผล
B5: • การวิเคราะห์และตัดสินใจบนพื้นฐานของข้อมูลอย่างสมเหตุสมผล | C5: 4 | D5: 1. สามารถวิเคราะห์แบบเจาะจงรายละเอียดได้ 2. ถูกต้องตามพื้นฐานข้อมูล 3. แยกแยะและเชื่อมโยงข้อมูลได้ 4. ตัดสินใจได้สมเหตุสมผล 5. คาดการปัญหาและวิธีแก้ไขในภาพรวมทั้งกระบวนการทำงาน
C6: 5 | D6: 1. วิเคราะห์ข้อมูลได้ครอบคลุมทุกองค์ประกอบและกระบวนการ 2. เจาะจงละเอียดครบถ้วน 3. ตัดสินใจโดยอิงข้อมูลเสมอ 4. ปิดความเสี่ยงได้ดี 5. มีแผนการสำรองเสมอ
A8: 2 | B8: ='Evaluate Interview form'!$W$6 -> การแก้ไขปัญหา (Problem Solving) | C8: 1 | D8: ไม่แก้ไขปัญหา / หนีปัญหา
B9: • การวิเคราะห์สถานการณ์และการคิดอย่างเป็นระบบ | C9: 2 | D9: แก้ไขปัญหา โดยศึกษาข้อมูลพื้นฐาน / ถามผู้รู้ เช่น ไล่ code แก้ bug ง่ายเองได้
B10: • กระบวนการคิดและลงมือปฏิบัติเพื่อหาทางออกที่ดีที่สุดสำหรับสถานการณ์ที่ยากลำบากหรือมีอุปสรรค | C10: 3 | D10: สามารถแก้ไขปัญหาที่ซับซ้อนปานกลางให้สำเร็จได้ด้วยตนเอง เช่น ไล่ code แก้ bug ที่มีความซับซ้อนเองได้
B11: • ความคิดสร้างสรรค์ในการหาทางออก | C11: 4 | D11: 1. แก้ไขปัญหาได้อย่างรวดเร็ว 2. ถูกต้องตามตรรกะ 3. สามารถนำกลุ่ม หรือ ทีม ในการแก้ไขปัญหาที่ซับซ้อนได้
C12: 5 | D12: 1. เชี่ยวชาญในการแก้ไขปัญหาที่มีความซับซ้อนสูง 2. มีแนวทางในการป้องกันการเกิดปัญหาเล็กก่อนที่จะเป็นปัญหาระดับองค์กร
A14: 3 | B14: ความเชี่ยวชาญด้านเทคนิค (Technical Skill) | C14: 1 | D14: ไม่มีความรู้ และทักษะที่จำเป็นในการทำงาน
B15: • ทักษะด้านการเขียนโปรแกรมหรือเครื่องมื่อต่างๆ | C15: 2 | D15: มีทักษะความรู้บ้างเล็กน้อยถึงปานกลาง/ ต้องมีคนแนะนำ เช่น เข้าใจหลักการของการแก้ไขปัญหาง่ายๆ
C16: 3 | D16: มีทักษะและความรู้เชิงลึกเหมาะสมกับลักษณะงาน คือ 1. รู้หลัการในการปฏิบัติอย่างละเอียด/ มีความรู้เรื่องนั้นอย่างละเอียด 2. ปฏิบัติได้ดี
C17: 4 | D17: มีความเชี่ยวชาญ คือ 1. รู้หลัการ 2. ปฏิบัติได้ดี 3. ใช้เวลาในการทำงานรวดเร็วกว่าปกติ 4. สอนหรือแนะนำผู้อื่นได้
C18: 5 | D18: 1. มีความเชี่ยวชาญ 2. สามารถวิเคราะห์ได้ถึงข้อดีข้อเสียของและโอกาสพัฒนาในการทำเทคโนโลยีนั้นมาใช้ในการทำงาน
A20: 4 | B20: ='Evaluate Interview form'!$W$9 -> การวางแผนและการจัดระเบียบ (Planning & Organizing) | C20: 1 | D20: ไม่มีแผนในการทำงาน / ทำๆ ไปให้งานเสร็จก็พอ
B21: • สามารถวางแผนการจัดการปัญหาหรือโปรเจกต์ได้อย่างมีประสิทธิภาพและลื่นไหล | C21: 2 | D21: สามารถระบุ จัดเรียงความสำคัญของปัญหาที่ต้องแก้ก่อนหลังได้
B22: • กำหนดเป้าหมาย การวิเคราะห์สถานการณ์ การกำหนดแนวทาง และการจัดสรรทรัพยากร | C22: 3 | D22: 1. วางแผนเป็นลำดับชัดเจน 2. สอดคล้องกับเวลาและปริมาณตามความยากง่ายของงาน
C23: 4 | D23: 1. วางแผนเป็นลำดับชัดเจน 2. สอดคล้องกับเวลาและปริมาณงาน 3. สอดคล้องกับกระบวนการทำงานในภาพรวมของทีม 4. มักได้ผลลัพธ์ที่ดีบ่อยครั้ง
C24: 5 | D24: มักมีการลำดับแผนงานชัดเจน 2. เหมาะสมกับเวลาและปริมาณงาน 3. สอดคล้องกับกระบวนการทำงานในภาพรวมของทีม 4. มักได้ผลลัพธ์ที่ดีบ่อยครั้ง 5. พร้อมคำนึงถึงผลกระทบที่จะเกิดรอบด้านและเตรียมวิธีแก้ไข
A26: 5 | B26: ='Evaluate Interview form'!$W$11 -> ทักษะการสื่อสารและเจรจา (Communication & Negotiation) | C26: 1 | D26: ถามคำตอบคำ/ ตอบตรงประเด็นน้อยกว่าครึ่งหนึ่งของคำถาม /จังหวะการพูดการสื่อสารทำให้ฟังยาก
B27: • สามารถในการอธิบายแนวคิด หรือ เรื่องราวต่างๆ ได้ชัดเจน • สามารถจูงใจหรือโน้วน้าวผู้อื่น ได้ | C27: 2 | D27: สื่อสารรู้เรื่อง เช่น เข้าใจเนื่อหาที่ผู้สมัครต้องการสื่อสาร
C28: 3 | D28: 1. สื่อสารได้อย่างคล่องแคล่ว 2. ถาม-ตอบ ตรงประเด็น อธิบายแนวคิดง่ายได้ชัดเจน 3. เจราต่อรอง/ ประสานงานกับคนในทีมและต่างทีมได้
C29: 4 | D29: 1. อธิบาย สิ่งต่างๆ ได้อย่างเป็นลำดับ 2. ฟังเข้าใจง่าย 3. สื่อสารแนวความคิดที่ซับซ้อนได้คล่องแคล่ว 4. เจราต่อรอง/ ประสานงานกับคนในองค์กรได้
C30: 5 | D30: มีทักษะการสื่อสารแบบองค์รวม คือ 1. สื่อสารแนวคิดที่ซับซ้อนได้เป็นลำดับเข้าใจง่าย 2. ถาม-ตอบตรงประเด็น 3. สร้างจุดดึงดูดและจูงใจให้ผู้คนสนใจฟังได้ในวงกว้าง เช่น ในที่ประชุม
A32: 6 | B32: ='Evaluate Interview form'!$W$14 -> ความกระตือรือร้น & ทัศนคติเชิงบวก (Proactive & Growth Mindset) | C32: 1 | D32: ไม่กระตือรือร้น / บุคลิกเป็นคนคิดช้า/ ทำช้า/ ไม่พยายามไขว่คว้า /ทัศนคติไม่
B33: • ความกระตือรือร้นที่จะทำงาน หาความรู้ และพยายามค้นหาวิธีการรับมือกับปัญหา | C33: 2 | D33: กระตือรือร้นเฉพาะในช่วงใกล้ส่งงาน/ เฉพาะช่วงที่จำเป็น
C34: 3 | D34: ชอบค้นคว้าหาความรู้ใหม่ๆ ที่ตนเองสนใจ / พัฒนาทักษะต่างที่ตนเองเห็นว่าจำเป็น / เริ่มทำงานทันทีเมื่อได้มอบหมาย
C35: 4 | D35: 1. มักค้นคว้าหาความรู้ใหม่ๆ เป็นประจำ/ พัฒนาทักษะใหม่ๆ เป็นประจำ 2. มักเริ่มทำงานทันทีและเสร็จก่อนเวลากำหนด
C36: 5 | D36: 1. มักค้นคว้าหาความรู้ใหม่ๆ เป็นประจำ/ พัฒนาทักษะใหม่ๆ เป็นประจำ 2. มักปฏิบัติงานทันทีและมักจะทำงานเกินความคาดหวัง
A38: 7 | B38: ='Evaluate Interview form'!$Z$6 -> การปรับตัว & การทำงานร่วมกันเป็นทีม (Adaptability & Teamwork) | C38: 1 | D38: ชอบทำงานคนเดียว/ ไม่ฟังความคิดเห็น /ไม่พูด / พูดไม่รู้เรื่อง
B39: • สามารถปรับตัวทำงานร่วมกับทีมได้ดี | C39: 2 | D39: รับฟังความคิดเห็น แต่ยังยึดตนเป็นศุนย์กลางอยู่บ้าง/ ทัศนคติไม่ตรงกัน/ ตรรกะในการคิดแตกต่างกันอยู่บ้าง
B40: • พร้อมรับฟังและยอมรับความเห็นต่าง | C40: 3 | D40: 1. มีความยืดหยุ่น 2. พร้อมรับฟังความคิดเห็น 3. สื่อสารกับทีมได้ดีพอประมาณ
C41: 4 | D41: 1. มีความยืดหยุ่น 2. สื่อสารกับทีมราบรื่น 3.รับฟังความคิดเห็น 4. ทัศนคติดี 5.แสดงความคิดเห็นอย่างสร้างสรรค์
C42: 5 | D42: 1. สื่อสารกับทีมราบรื่น 2. รับฟังความคิดเห็น 3. ทัศนคติดี 4. มักแสดงความคิดเห็นอย่างสร้างสรรค์ 5. พร้อมช่วยเหลือทีมเสมอ
A44: 8 | B44: ='Evaluate Interview form (Demo)'!$W$8 -> ความฉับไวในการเรียนรู้ (Learning Agility) | C44: 1 | D44: ไม่ชอบการเรียนรู้ / ไม่ค่อยเข้าใจในสิ่งที่เรียนรู้ / เข้าใจยาก
B45: • เรียนรู้เทคโนโลยีใหม่ ๆ ได้เร็วและต่อเนื่อง | C45: 2 | D45: 1. ใช้เวลาในการเรียนรู้ /ทำความเข้าใจในเรื่องง่ายได้ 2. สามารถปรับใช้ได้ภายในเวลาที่เหมาะสม
B46: • ความสามารถในการเรียนรู้ ปรับตัว และประยุกต์ใช้ความรู้ใหม่ๆ ได้อย่างรวดเร็วและมีประสิทธิภาพ | C46: 3 | D46: 1. เข้าใจสิ่งที่มีซับซ้อนได้รวดเร็ว 2. สามารถปรับใช้ได้ภายในเวลาที่เหมาะสม
C47: 4 | D47: 1. มักจะหาโอกาสเรียนรู้สิ่งใหม่ 2. เข้าใจสิ่งที่มีความซับซ้อนได้รวดเร็ว
...

Sheet Competency detail
A1: ข้อ | B1: สมรรถนะหลัก | C1: ระดับ | D1: พฤติกรรมขณะสัมภาษณ์ | E1: ทีมตรวจสอบและแก้ไข | F1: สรุป ความคาดหวัง
A2: 1 | B2: ='Evaluate Interview form'!$T$5 -> การคิดวิเคราะห์ & การตัดสินใจ (Analytical Thinking & Decision Making) | C2: 1 | D2: ไม่ตัดสินใจ /ไม่สามารถคิดวิเคราะห์ได้ เช่น วิเคราะห์หาสาเหตุไม่ได้
B3: • ความสามารถตัดสินใจอย่างมีเหตุผล โดยผ่านการวิเคราะห์ ประมวลข้อมูล และสรุปประเด็นสำคัญ | C3: 2 | D3: 1. สามารถวิเคราะห์ข้อมูลเบื้องต้น 2.ตัดสินใจได้อย่างสมเหตุสมผลภายใต้พื้นฐานของข้อมูล
B4: • การคิดจำแนกแจกแจงองค์ประกอบต่างๆ ของปัญหาออกเป็นประเด็นย่อยๆ ในหลายๆแง่มุม แล้วนำมาวิเคราะห์และเชื่อมโยง | C4: 3 | D4: 1. สามารถวิเคราะห์แบบเจาะจงรายละเอียด 2. แยกแยะและเชื่อมโยงได้ 3. ถูกต้องตามพื้นฐานข้อมูล 4. ตัดสินใจได้สมเหตุสมผล
B5: • การวิเคราะห์และตัดสินใจบนพื้นฐานของข้อมูลอย่างสมเหตุสมผล | C5: 4 | D5: 1. สามารถวิเคราะห์แบบเจาะจงรายละเอียดได้ 2. ถูกต้องตามพื้นฐานข้อมูล 3. แยกแยะและเชื่อมโยงข้อมูลได้ 4. ตัดสินใจได้สมเหตุสมผล 5. คาดการปัญหาและวิธีแก้ไขในภาพรวมทั้งกระบวนการทำงาน
C6: 5 | D6: 1. วิเคราะห์ข้อมูลได้ครอบคลุมทุกองค์ประกอบและกระบวนการ 2. เจาะจงละเอียดครบถ้วน 3. ตัดสินใจโดยอิงข้อมูลเสมอ 4. ปิดความเสี่ยงได้ดี 5. มีแผนการสำรองเสมอ
A8: 2 | B8: ='Evaluate Interview form'!$W$6 -> การแก้ไขปัญหา (Problem Solving) | C8: 1 | D8: ไม่แก้ไขปัญหา / หนีปัญหา
B9: • การวิเคราะห์สถานการณ์และการคิดอย่างเป็นระบบ | C9: 2 | D9: แก้ไขปัญหา โดยศึกษาข้อมูลพื้นฐาน / ถามผู้รู้ เช่น ไล่ code แก้ bug ง่ายเองได้
B10: • กระบวนการคิดและลงมือปฏิบัติเพื่อหาทางออกที่ดีที่สุดสำหรับสถานการณ์ที่ยากลำบากหรือมีอุปสรรค | C10: 3 | D10: สามารถแก้ไขปัญหาที่ซับซ้อนปานกลางให้สำเร็จได้ด้วยตนเอง เช่น ไล่ code แก้ bug ที่มีความซับซ้อนเองได้
B11: • ความคิดสร้างสรรค์ในการหาทางออก | C11: 4 | D11: 1. แก้ไขปัญหาได้อย่างรวดเร็ว 2. ถูกต้องตามตรรกะ 3. สามารถนำกลุ่ม หรือ ทีม ในการแก้ไขปัญหาที่ซับซ้อนได้
C12: 5 | D12: 1. เชี่ยวชาญในการแก้ไขปัญหาที่มีความซับซ้อนสูง 2. มีแนวทางในการป้องกันการเกิดปัญหาเล็กก่อนที่จะเป็นปัญหาระดับองค์กร
A14: 3 | B14: ความเชี่ยวชาญด้านเทคนิค (Technical Skill) | C14: 1 | D14: ไม่มีความรู้ และทักษะที่จำเป็นในการทำงาน
B15: • ทักษะด้านการเขียนโปรแกรมหรือเครื่องมื่อต่างๆ | C15: 2 | D15: มีทักษะความรู้บ้างเล็กน้อยถึงปานกลาง/ ต้องมีคนแนะนำ เช่น เข้าใจหลักการของการแก้ไขปัญหาง่ายๆ
C16: 3 | D16: มีทักษะและความรู้เชิงลึกเหมาะสมกับลักษณะงาน คือ 1. รู้หลัการในการปฏิบัติอย่างละเอียด/ มีความรู้เรื่องนั้นอย่างละเอียด 2. ปฏิบัติได้ดี
C17: 4 | D17: มีความเชี่ยวชาญ คือ 1. รู้หลัการ 2. ปฏิบัติได้ดี 3. ใช้เวลาในการทำงานรวดเร็วกว่าปกติ 4. สอนหรือแนะนำผู้อื่นได้
C18: 5 | D18: 1. มีความเชี่ยวชาญ 2. สามารถวิเคราะห์ได้ถึงข้อดีข้อเสียของและโอกาสพัฒนาในการทำเทคโนโลยีนั้นมาใช้ในการทำงาน
A20: 4 | B20: ='Evaluate Interview form'!$W$9 -> การวางแผนและการจัดระเบียบ (Planning & Organizing) | C20: 1 | D20: ไม่มีแผนในการทำงาน / ทำๆ ไปให้งานเสร็จก็พอ
B21: • สามารถวางแผนการจัดการปัญหาหรือโปรเจกต์ได้อย่างมีประสิทธิภาพและลื่นไหล | C21: 2 | D21: สามารถระบุ จัดเรียงความสำคัญของปัญหาที่ต้องแก้ก่อนหลังได้
B22: • กำหนดเป้าหมาย การวิเคราะห์สถานการณ์ การกำหนดแนวทาง และการจัดสรรทรัพยากร | C22: 3 | D22: 1. วางแผนเป็นลำดับชัดเจน 2. สอดคล้องกับเวลาและปริมาณตามความยากง่ายของงาน
C23: 4 | D23: 1. วางแผนเป็นลำดับชัดเจน 2. สอดคล้องกับเวลาและปริมาณงาน 3. สอดคล้องกับกระบวนการทำงานในภาพรวมของทีม 4. มักได้ผลลัพธ์ที่ดีบ่อยครั้ง
C24: 5 | D24: มักมีการลำดับแผนงานชัดเจน 2. เหมาะสมกับเวลาและปริมาณงาน 3. สอดคล้องกับกระบวนการทำงานในภาพรวมของทีม 4. มักได้ผลลัพธ์ที่ดีบ่อยครั้ง 5. พร้อมคำนึงถึงผลกระทบที่จะเกิดรอบด้านและเตรียมวิธีแก้ไข
A26: 5 | B26: ='Evaluate Interview form'!$W$11 -> ทักษะการสื่อสารและเจรจา (Communication & Negotiation) | C26: 1 | D26: ถามคำตอบคำ/ ตอบตรงประเด็นน้อยกว่าครึ่งหนึ่งของคำถาม /จังหวะการพูดการสื่อสารทำให้ฟังยาก
B27: • สามารถในการอธิบายแนวคิด หรือ เรื่องราวต่างๆ ได้ชัดเจน • สามารถจูงใจหรือโน้วน้าวผู้อื่น ได้ | C27: 2 | D27: สื่อสารรู้เรื่อง เช่น เข้าใจเนื่อหาที่ผู้สมัครต้องการสื่อสาร
C28: 3 | D28: 1. สื่อสารได้อย่างคล่องแคล่ว 2. ถาม-ตอบ ตรงประเด็น อธิบายแนวคิดง่ายได้ชัดเจน 3. เจราต่อรอง/ ประสานงานกับคนในทีมและต่างทีมได้
C29: 4 | D29: 1. อธิบาย สิ่งต่างๆ ได้อย่างเป็นลำดับ 2. ฟังเข้าใจง่าย 3. สื่อสารแนวความคิดที่ซับซ้อนได้คล่องแคล่ว 4. เจราต่อรอง/ ประสานงานกับคนในองค์กรได้
C30: 5 | D30: มีทักษะการสื่อสารแบบองค์รวม คือ 1. สื่อสารแนวคิดที่ซับซ้อนได้เป็นลำดับเข้าใจง่าย 2. ถาม-ตอบตรงประเด็น 3. สร้างจุดดึงดูดและจูงใจให้ผู้คนสนใจฟังได้ในวงกว้าง เช่น ในที่ประชุม
A32: 6 | B32: ='Evaluate Interview form'!$W$14 -> ความกระตือรือร้น & ทัศนคติเชิงบวก (Proactive & Growth Mindset) | C32: 1 | D32: ไม่กระตือรือร้น / บุคลิกเป็นคนคิดช้า/ ทำช้า/ ไม่พยายามไขว่คว้า /ทัศนคติไม่
B33: • ความกระตือรือร้นที่จะทำงาน หาความรู้ และพยายามค้นหาวิธีการรับมือกับปัญหา | C33: 2 | D33: กระตือรือร้นเฉพาะในช่วงใกล้ส่งงาน/ เฉพาะช่วงที่จำเป็น
